Workbook

Sheet Anleitung
B2: Kapitalwertmodell: E-Auto kaufen, leasen oder LPG-Bestandsfahrzeug weiterfahren
B3: Recherchestand 4. August 2026. Quellen jeweils im betreffenden Blatt.
B5: Legende
B6: BLAU = Eingabe / Stellschraube. Nur diese Zellen überschreiben.
B7: SCHWARZ = Formel. GRÜN = Verweis auf ein anderes Blatt. GELB = ergebnistreibende Annahme.
B9: Die vier Handlungsalternativen
B10: A1 E-Auto sofort kaufen
B11: A2 E-Auto sofort leasen (Kette aus zwei 36-Monats-Verträgen)
B12: A3 vergleichbaren Verbrenner als Neuwagen kaufen
B13: A4 Bestandsfahrzeug reparieren, die Restnutzungsdauer abfahren, danach E-Auto kaufen
B15: Warum A4 eine Ersatzbeschaffung enthält
B16: Das Bestandsfahrzeug hält nur noch begrenzt. Ein Vergleich 'E-Auto sechs Jahre' gegen 'alter Wagen sechs Jahre'
... B32: Annahmen · Foerdermatrix · Modelle (Marktübersicht + Kapitalwertvergleich aller Modelle) · Cashflow · Ergebnis · Sensitivitaet

Sheet Annahmen
B2: Annahmen – alle blauen Zellen sind Eingaben
B3: Realistisch vorbelegt. Bitte auf die eigene Situation anpassen.
B5: 1 Fahrprofil und Kapitalmarkt
B6: Fahrleistung (km pro Jahr) | C6: 12000 | D6: Wichtigster Treiber der laufenden Kostendifferenz
B7: Betrachtungshorizont (Jahre) | C7: 6 | D7: 6 Jahre = 2 Leasingzyklen; alle Alternativen decken diesen Zeitraum ab
B8: Horizont in Monaten | C8: =C7*12 -> 72
B9: Kalkulationszinssatz p.a. | C9: 0.03 | D9: Opportunitätskosten: entgangene Anlagerendite bzw. Kreditzins
B10: Monatszinssatz (konform) | C10: =(1+C9)^(1/12)-1 -> 0.0024662698 | D10: i_m = (1+i_a)^(1/12) − 1
B11: Energiepreissteigerung p.a. | C11: 0.02 | D11: Wirkt auf Strom, Benzin und LPG gleichermaßen
B12: Fahrzeugpreissteigerung p.a. | C12: 0.015 | D12: Für das Ersatzfahrzeug in Alternative A4
B14: 2 Förderung
B15: Zu versteuerndes Haushaltseinkommen (€/Jahr) | C15: 55000 | D15: Ø der beiden aktuellsten Steuerbescheide, Partnereinkommen addiert
B16: Kinder unter 18 im Haushalt | C16: 0 | D16: je 500 € Bonus, maximal 1.000 €
B17: Förderung BEV | C17: =INDEX(Foerdermatrix!C8:E13,MATCH(C15,Foerdermatrix!H8:H13,1),MIN(C16,2)+1) -> 4000 | D17: Automatischer Lookup aus der BAFA-Staffel
B18: Förderung Plug-in-Hybrid (nur Information) | C18: =INDEX(Foerdermatrix!C17:E22,MATCH(C15,Foerdermatrix!H8:H13,1),MIN(C16,2)+1) -> 2500
B19: Auszahlungsmonat der Förderung nach Zulassung | C19: 4 | D19: Antrag erst nach Zulassung, danach BAFA-Bearbeitung
B20: THG-Prämie (€/Jahr, nur BEV) | C20: 300 | D20: 2026 rund 250–370 €, für Privatpersonen steuerfrei
B21: Förderung beim Ersatzkauf in A4 noch verfügbar? (1=ja, 0=nein) | C21: 1 | D21: Budget 3 Mrd. € gedeckelt, Programm endet spätestens 31.12.2029 – auf 0 setzen für den Pessimismusfall
B23: 3 Energiepreise
B24: Strompreis zu Hause / Wallbox (€/kWh) | C24: 0.3 | D24: Neukundentarife Aug. 2026 rd. 0,26 €; Ø Haushalt lt. BDEW 0,37 €
B25: Anteil Heimladen | C25: 0.8 | D25: Ohne eigene Lademöglichkeit auf 0 setzen – kippt das Ergebnis häufig
B26: Strompreis öffentlich (€/kWh) | C26: 0.55 | D26: AC ab 0,44 €, DC ab 0,45 € mit Tarif; ad hoc deutlich teurer
B27: Mischstrompreis (€/kWh) | C27: =C24*C25+C26*(1-C25) -> 0.35
B28: Benzinpreis Super E10 (€/l) | C28: 2.1 | D28: ADAC-Bundesschnitt Ende Juli 2026: 2,139 €/l (Irankrieg-bedingt hoch)
B29: Autogaspreis LPG (€/l) | C29: 0.99 | D29: Ihr Wert. Zur Einordnung: nationaler Schnitt 2026 rd. 1,10–1,22 €/l (glpautogas), Jahresmittel 1,148 € (autogasvergleich.de)
B31: 4 Alternative A1 – E-Auto kaufen
B32: Modell | C32: Hyundai Inster (Beispiel) | D32: Auswahl aus dem Blatt 'Modelle' übertragen
B33: Listenpreis (€, brutto) | C33: 23900 | D33: Quelle: AutoScout24-Marktübersicht 02/2026
B34: Verbrauch WLTP (kWh/100 km) | C34: 15.1 | D34: Herstellerangabe
B35: Realaufschlag auf WLTP | C35: 1.18 | D35: ADAC-Auswertung: real rund +18 % im Jahresmittel inkl. Ladeverluste
B36: Rechenverbrauch (kWh/100 km) | C36: =C34*C35 -> 17.818
B37: Jährliche Wertverlustrate BEV | C37: 0.15 | D37: Daraus wird jeder Restwert altersgerecht abgeleitet – größte Unsicherheit
B38: Restwert am Horizontende (€) | C38: =C33*(1-C37)^C7 -> 9013.8734
B39: Versicherung (€/Jahr) | C39: 750 | D39: E-Autos oft etwas teurer wegen HV-Reparaturkosten
B40: Wartung und Verschleiß (€/Jahr) | C40: 300 | D40: Lt. ADAC 30–50 % günstiger als beim Verbrenner
B41: Wallbox inkl. Installation (einmalig, €) | C41: 1500 | D41: Spanne 1.000–2.500 €; ohne eigenen Stellplatz auf 0 setzen
B42: Kfz-Steuer (€/Jahr) | C42: 0 | D42: BEV bis 31.12.2035 befreit, max. 10 Jahre ab Erstzulassung
B44: 5 Alternative A2 – dasselbe E-Auto leasen
B45: Leasingfaktor OHNE eingerechnete Förderung | C45: 1 | D45: Rate in % des Listenpreises. DIESER WERT entscheidet den Kauf-Leasing-Vergleich – unbedingt durch ein konkretes Angebot ersetzen. Beworbene Faktoren von 0,15–0,35 enthalten die Prämie bereits als Sonderzahlung und dürfen hier nicht eingetragen werden.
B46: Monatsrate (€) | C46: =C33*C45/100 -> 239
...

Sheet Foerdermatrix
B2: Fördersätze E-Auto-Kaufprämie 2026 (BAFA / Bundesumweltministerium)
B3: Antrag über die Förderzentrale Deutschland seit 19.05.2026, rückwirkend für Erstzulassungen ab 01.01.2026. Mindesthaltedauer 36 Monate. Nur Privatpersonen, Neufahrzeuge Klasse M1, Kauf und Leasing.
B4: Quelle: ADAC 'E-Auto-Förderung 2026', Stand 15.07.2026; Fördersätze laut Bundesumweltministerium
B6: Reine Elektrofahrzeuge (BEV / Brennstoffzelle)
B7: Zu versteuerndes Haushaltseinkommen | C7: ohne Kind | D7: 1 Kind | E7: 2+ Kinder | H7: Untergrenze (Hilfsspalte für MATCH)
B8: bis 45.000 € | C8: 5000 | D8: 5500 | E8: 6000 | H8: 0
B9: 45.001 bis 60.000 € | C9: 4000 | D9: 4500 | E9: 5000 | H9: 45000.01
B10: 60.001 bis 80.000 € | C10: 3000 | D10: 3500 | E10: 4000 | H10: 60000.01
B11: 80.001 bis 85.000 € | C11: 0 | D11: 3500 | E11: 4000 | H11: 80000.01
B12: 85.001 bis 90.000 € | C12: 0 | D12: 0 | E12: 4000 | H12: 85000.01
B13: über 90.000 € | C13: 0 | D13: 0 | E13: 0 | H13: 90000.01
B15: Plug-in-Hybride / Range-Extender (bis 30.06.2027, ≤60 g CO2/km oder ≥80 km E-Reichweite)
B16: Zu versteuerndes Haushaltseinkommen | C16: ohne Kind | D16: 1 Kind | E16: 2+ Kinder
B17: bis 45.000 € | C17: 3500 | D17: 4000 | E17: 4500
B18: 45.001 bis 60.000 € | C18: 2500 | D18: 3000 | E18: 3500
B19: 60.001 bis 80.000 € | C19: 1500 | D19: 2000 | E19: 2500
B20: 80.001 bis 85.000 € | C20: 0 | D20: 2000 | E20: 2500
B21: 85.001 bis 90.000 € | C21: 0 | D21: 0 | E21: 2500
B22: über 90.000 € | C22: 0 | D22: 0 | E22: 0
B24: Weitere Förderbausteine
B25: Kfz-Steuerbefreiung reine BEV | C25: bis 31.12.2035, max. 10 Jahre ab Erstzulassung; Erstzulassung bis Ende 2030
B26: THG-Quote | C26: jährlich neu beantragbar, 2026 rd. 250–370 €, für Privatpersonen steuerfrei
B27: Dienstwagen (0,25-%-Regel) | C27: Bruttolistenpreisgrenze seit 01.07.2025 auf 100.000 € angehoben
B28: Turboabschreibung (Betriebsvermögen) | C28: 75 % im 1. Jahr, dann 10/5/5/3/2 %, Anschaffung bis 31.12.2027
B30: Haushaltseinkommen: Ø der beiden aktuellsten Steuerbescheide (max. 3 Jahre alt); bei Ehe, Lebenspartnerschaft oder eheähnlicher Gemeinschaft werden beide zvE addiert.

Sheet Modelle
B2: Marktübersicht und Kapitalwertvergleich aller recherchierten E-Autos
B3: Listenpreise = Basisversion brutto, Stand Februar bis Juli 2026, ohne Herstellerrabatte. Blaue Werte bei Bedarf mit tagesaktuellen Konfiguratordaten überschreiben.
B5: Modell | C5: Segment | D5: Listenpreis | E5: WLTP kWh/100km | F5: Rechen- verbrauch | G5: Reichweite WLTP km | H5: Förderung | I5: Effektivpreis | J5: Energie €/100 km | K5: Energie €/Jahr | L5: Quelle
B6: Dacia Spring 45 | C6: Kleinstwagen | D6: 18700 | E6: 14.6 | F6: =E6*Annahmen!$C$35 -> 17.228 | G6: 220 | H6: =Annahmen!$C$17 -> 4000 | I6: =D6-H6 -> 14700 | J6: =F6*Annahmen!$C$27 -> 6.0298 | K6: =J6*Annahmen!$C$6/100 -> 723.576 | L6: AutoScout24 02/2026; ARI-Marktübersicht 06/2026
B7: Leapmotor T03 | C7: Kleinstwagen | D7: 18900 | E7: 16.5 | F7: =E7*Annahmen!$C$35 -> 19.47 | G7: 265 | H7: =Annahmen!$C$17 -> 4000 | I7: =D7-H7 -> 14900 | J7: =F7*Annahmen!$C$27 -> 6.8145 | K7: =J7*Annahmen!$C$6/100 -> 817.74 | L7: AutoScout24 02/2026 (Verbrauch geschätzt)
B8: Renault Twingo E-Tech | C8: Kleinstwagen | D8: 19900 | E8: 14 | F8: =E8*Annahmen!$C$35 -> 16.52 | G8: 263 | H8: =Annahmen!$C$17 -> 4000 | I8: =D8-H8 -> 15900 | J8: =F8*Annahmen!$C$27 -> 5.782 | K8: =J8*Annahmen!$C$6/100 -> 693.84 | L8: AutoScout24 02/2026 (Verbrauch geschätzt)
B9: Citroën ë-C3 | C9: Kleinwagen | D9: 19990 | E9: 17 | F9: =E9*Annahmen!$C$35 -> 20.06 | G9: 320 | H9: =Annahmen!$C$17 -> 4000 | I9: =D9-H9 -> 15990 | J9: =F9*Annahmen!$C$27 -> 7.021 | K9: =J9*Annahmen!$C$6/100 -> 842.52 | L9: AutoScout24 02/2026 (Verbrauch geschätzt)
B10: BYD Dolphin Surf | C10: Kleinwagen | D10: 22990 | E10: 16 | F10: =E10*Annahmen!$C$35 -> 18.88 | G10: 322 | H10: =Annahmen!$C$17 -> 4000 | I10: =D10-H10 -> 18990 | J10: =F10*Annahmen!$C$27 -> 6.608 | K10: =J10*Annahmen!$C$6/100 -> 792.96 | L10: AutoScout24 02/2026 (Verbrauch geschätzt)
B11: Hyundai Inster | C11: Kleinwagen | D11: 23900 | E11: 15.1 | F11: =E11*Annahmen!$C$35 -> 17.818 | G11: 355 | H11: =Annahmen!$C$17 -> 4000 | I11: =D11-H11 -> 19900 | J11: =F11*Annahmen!$C$27 -> 6.2363 | K11: =J11*Annahmen!$C$6/100 -> 748.356 | L11: AutoScout24 02/2026; ADAC-Test rd. 15,5 real
B12: Fiat Grande Panda | C12: Kleinwagen | D12: 24990 | E12: 17 | F12: =E12*Annahmen!$C$35 -> 20.06 | G12: 320 | H12: =Annahmen!$C$17 -> 4000 | I12: =D12-H12 -> 20990 | J12: =F12*Annahmen!$C$27 -> 7.021 | K12: =J12*Annahmen!$C$6/100 -> 842.52 | L12: AutoScout24 02/2026 (Verbrauch geschätzt)
B13: VW ID.Polo | C13: Kleinwagen | D13: 24995 | E13: 14.5 | F13: =E13*Annahmen!$C$35 -> 17.11 | G13: 450 | H13: =Annahmen!$C$17 -> 4000 | I13: =D13-H13 -> 20995 | J13: =F13*Annahmen!$C$27 -> 5.9885 | K13: =J13*Annahmen!$C$6/100 -> 718.62 | L13: AUTO BILD 07/2026, Marktstart September 2026
B14: Skoda Epiq | C14: Kompakt-SUV | D14: 25900 | E14: 15.5 | F14: =E14*Annahmen!$C$35 -> 18.29 | G14: 430 | H14: =Annahmen!$C$17 -> 4000 | I14: =D14-H14 -> 21900 | J14: =F14*Annahmen!$C$27 -> 6.4015 | K14: =J14*Annahmen!$C$6/100 -> 768.18 | L14: AUTO BILD 07/2026, Marktstart September 2026
B15: Renault 5 E-Tech | C15: Kleinwagen | D15: 28000 | E15: 15 | F15: =E15*Annahmen!$C$35 -> 17.7 | G15: 410 | H15: =Annahmen!$C$17 -> 4000 | I15: =D15-H15 -> 24000 | J15: =F15*Annahmen!$C$27 -> 6.195 | K15: =J15*Annahmen!$C$6/100 -> 743.4 | L15: AutoScout24 02/2026 (Verbrauch geschätzt)
B16: Opel Frontera Electric | C16: Kompakt-SUV | D16: 28990 | E16: 18.5 | F16: =E16*Annahmen!$C$35 -> 21.83 | G16: 305 | H16: =Annahmen!$C$17 -> 4000 | I16: =D16-H16 -> 24990 | J16: =F16*Annahmen!$C$27 -> 7.6405 | K16: =J16*Annahmen!$C$6/100 -> 916.86 | L16: AutoScout24 02/2026 (Verbrauch geschätzt)
B17: Hyundai Ioniq 3 | C17: Kleinwagen | D17: 35000 | E17: 14.5 | F17: =E17*Annahmen!$C$35 -> 17.11 | G17: 490 | H17: =Annahmen!$C$17 -> 4000 | I17: =D17-H17 -> 31000 | J17: =F17*Annahmen!$C$27 -> 5.9885 | K17: =J17*Annahmen!$C$6/100 -> 718.62 | L17: AUTO BILD 07/2026, Marktstart Ende 2026, Preis ca.
... B20: Kia EV3 LR (81 kWh) | C20: Kompakt-SUV | D20: 43890 | E20: 16 | F20: =E20*Annahmen!$C$35 -> 18.88 | G20: 605 | H20: =Annahmen!$C$17 -> 4000 | I20: =D20-H20 -> 39890 | J20: =F20*Annahmen!$C$27 -> 6.608 | K20: =J20*Annahmen!$C$6/100 -> 792.96 | L20: autocolumn 03/2026
B23: Rechenhilfen (jährliche Zahlungsweise, geschlossene Form)
B24: Rentenbarwertfaktor RBF(n) | C24: =((1+Annahmen!$C$9)^Annahmen!$C$7-1)/(Annahmen!$C$9*(1+Annahmen!$C$9)^Annahmen!$C$7) -> 5.4171914 | E24: konstante Zahlungen über den Horizont
B25: Rentenbarwertfaktor mit Wachstum RBF_g(n) | C25: =(1-((1+Annahmen!$C$11)/(1+Annahmen!$C$9))^Annahmen!$C$7)/(Annahmen!$C$9-Annahmen!$C$11) -> 5.6856703 | E25: Energiekosten, wachsen mit g
B26: RBF über die Restnutzungsdauer | C26: =((1+Annahmen!$C$9)^Annahmen!$C$67-1)/(Annahmen!$C$9*(1+Annahmen!$C$9)^Annahmen!$C$67) -> 1.9134697
B27: RBF_g über die Restnutzungsdauer | C27: =(1-((1+Annahmen!$C$11)/(1+Annahmen!$C$9))^Annahmen!$C$67)/(Annahmen!$C$9-Annahmen!$C$11) -> 1.9323216
B29: A4 Barwert Status quo: Bestand + Ersatzbeschaffung | C29: =Annahmen!$C$66+$C$27*(Annahmen!$C$6/100*Annahmen!$C$72)+$C$26*(Annahmen!$C$73+Annahmen!$C$74+Annahmen!$C$75)-Annahmen!$C$76/(1+Annahmen!$C$9)^Annahmen!$C$67+(Annahmen!$C$81+Annahmen!$C$41)/(1+Annahmen!$C$9)^Annahmen!$C$67-Annahmen!$C$17*Annahmen!$C$21/(1+Annahmen!$C$9)^(Annahmen!$C$67+Annahmen!$C$19/12)+($C$24-$C$26)*(Annahmen!$C$39+Annahmen!$C$40+Annahmen!$C$42-Annahmen!$C$20)+($C$25-$C$27)*(Annahmen!$C$6/100*Annahmen!$C$36*Annahmen!$C$27)-Annahmen!$C$82/(1+Annahmen!$C$9)^Annahmen!$C$7 -> 22613.1 | E29: Referenzwert, gegen den alle Modelle gemessen werden
B30: A3 Barwert Verbrenner-Neuwagen | C30: =Annahmen!$C$57-Annahmen!$C$77-Annahmen!$C$60/(1+Annahmen!$C$9)^Annahmen!$C$7+$C$24*(Annahmen!$C$61+Annahmen!$C$62+Annahmen!$C$63)+$C$25*(Annahmen!$C$6/100*Annahmen!$C$58*Annahmen!$C$28) -> 28420.529
B33: Kapitalwertvergleich: alle Modelle gegen den Status quo
B34: Ausgewiesen ist der Barwert der Auszahlungen über den Betrachtungshorizont, positiv dargestellt. Je kleiner, desto besser. Alle Modelle mit identischer Versicherungs-, Wartungs- und Restwertannahme.
B36: Modell | C36: Listenpreis | D36: Effektivpreis nach Förderung | E36: Barwert KAUF | F36: Annuität KAUF | G36: Vollkosten €/km | H36: Barwert LEASING | I36: Vorteil Kauf ggü. Status quo | J36: Rang (Kauf)
B37: =B6 -> Dacia Spring 45 | C37: =D6 -> 18700 | D37: =I6 -> 14700 | E37: =(D6+Annahmen!$C$41)-Annahmen!$C$77-Annahmen!$C$17/(1+Annahmen!$C$10)^Annahmen!$C$19-D6*(1-Annahmen!$C$37)^Annahmen!$C$7/(1+Annahmen!$C$9)^Annahmen!$C$7+$C$24*(Annahmen!$C$39+Annahmen!$C$40+Annahmen!$C$42-Annahmen!$C$20)+$C$25*(Annahmen!$C$6/100*F6*Annahmen!$C$27) -> 17009.605 | F37: =E37/$C$24 -> 3139.9305 | G37: =F37/Annahmen!$C$6 -> 0.26166087 | H37: =12*(D6*Annahmen!$C$45/100)*$C$24+Annahmen!$C$49+Annahmen!$C$41-Annahmen!$C$77-Annahmen!$C$17/(1+Annahmen!$C$10)^Annahmen!$C$19+$C$24*(Annahmen!$C$53+Annahmen!$C$54-Annahmen!$C$20)+$C$25*(Annahmen!$C$6/100*F6*Annahmen!$C$27)+Annahmen!$C$52/(1+Annahmen!$C$9)^(Annahmen!$C$47/12)+IF(Annahmen!$C$7>=2*Annahmen!$C$47/12,Annahmen!$C$52/(1+Annahmen!$C$9)^(2*Annahmen!$C$47/12),0) -> 17634.195 | I37: =$C$29-E37 -> 5603.4955 | J37: =RANK(E37,$E$37:$E$51,1) -> 1
B38: =B7 -> Leapmotor T03 | C38: =D7 -> 18900 | D38: =I7 -> 14900 | E38: =(D7+Annahmen!$C$41)-Annahmen!$C$77-Annahmen!$C$17/(1+Annahmen!$C$10)^Annahmen!$C$19-D7*(1-Annahmen!$C$37)^Annahmen!$C$7/(1+Annahmen!$C$9)^Annahmen!$C$7+$C$24*(Annahmen!$C$39+Annahmen!$C$40+Annahmen!$C$42-Annahmen!$C$20)+$C$25*(Annahmen!$C$6/100*F7*Annahmen!$C$27) -> 17681.819 | F38: =E38/$C$24 -> 3264.0195 | G38: =F38/Annahmen!$C$6 -> 0.27200163 | H38: =12*(D7*Annahmen!$C$45/100)*$C$24+Annahmen!$C$49+Annahmen!$C$41-Annahmen!$C$77-Annahmen!$C$17/(1+Annahmen!$C$10)^Annahmen!$C$19+$C$24*(Annahmen!$C$53+Annahmen!$C$54-Annahmen!$C$20)+$C$25*(Annahmen!$C$6/100*F7*Annahmen!$C$27)+Annahmen!$C$52/(1+Annahmen!$C$9)^(Annahmen!$C$47/12)+IF(Annahmen!$C$7>=2*Annahmen!$C$47/12,Annahmen!$C$52/(1+Annahmen!$C$9)^(2*Annahmen!$C$47/12),0) -> 18299.593 | I38: =$C$29-E38 -> 4931.2814 | J38: =RANK(E38,$E$37:$E$51,1) -> 3
B39: =B8 -> Renault Twingo E-Tech | C39: =D8 -> 19900 | D39: =I8 -> 15900 | E39: =(D8+Annahmen!$C$41)-Annahmen!$C$77-Annahmen!$C$17/(1+Annahmen!$C$10)^Annahmen!$C$19-D8*(1-Annahmen!$C$37)^Annahmen!$C$7/(1+Annahmen!$C$9)^Annahmen!$C$7+$C$24*(Annahmen!$C$39+Annahmen!$C$40+Annahmen!$C$42-Annahmen!$C$20)+$C$25*(Annahmen!$C$6/100*F8*Annahmen!$C$27) -> 17661.507 | F39: =E39/$C$24 -> 3260.2701 | G39: =F39/Annahmen!$C$6 -> 0.27168918 | H39: =12*(D8*Annahmen!$C$45/100)*$C$24+Annahmen!$C$49+Annahmen!$C$41-Annahmen!$C$77-Annahmen!$C$17/(1+Annahmen!$C$10)^Annahmen!$C$19+$C$24*(Annahmen!$C$53+Annahmen!$C$54-Annahmen!$C$20)+$C$25*(Annahmen!$C$6/100*F8*Annahmen!$C$27)+Annahmen!$C$52/(1+Annahmen!$C$9)^(Annahmen!$C$47/12)+IF(Annahmen!$C$7>=2*Annahmen!$C$47/12,Annahmen!$C$52/(1+Annahmen!$C$9)^(2*Annahmen!$C$47/12),0) -> 18245.201 | I39: =$C$29-E39 -> 4951.5928 | J39: =RANK(E39,$E$37:$E$51,1) -> 2
B40: =B9 -> Citroën ë-C3 | C40: =D9 -> 19990 | D40: =I9 -> 15990 | E40: =(D9+Annahmen!$C$41)-Annahmen!$C$77-Annahmen!$C$17/(1+Annahmen!$C$10)^Annahmen!$C$19-D9*(1-Annahmen!$C$37)^Annahmen!$C$7/(1+Annahmen!$C$9)^Annahmen!$C$7+$C$24*(Annahmen!$C$39+Annahmen!$C$40+Annahmen!$C$42-Annahmen!$C$20)+$C$25*(Annahmen!$C$6/100*F9*Annahmen!$C$27) -> 18568.426 | F40: =E40/$C$24 -> 3427.685 | G40: =F40/Annahmen!$C$6 -> 0.28564041 | H40: =12*(D9*Annahmen!$C$45/100)*$C$24+Annahmen!$C$49+Annahmen!$C$41-Annahmen!$C$77-Annahmen!$C$17/(1+Annahmen!$C$10)^Annahmen!$C$19+$C$24*(Annahmen!$C$53+Annahmen!$C$54-Annahmen!$C$20)+$C$25*(Annahmen!$C$6/100*F9*Annahmen!$C$27)+Annahmen!$C$52/(1+Annahmen!$C$9)^(Annahmen!$C$47/12)+IF(Annahmen!$C$7>=2*Annahmen!$C$47/12,Annahmen!$C$52/(1+Annahmen!$C$9)^(2*Annahmen!$C$47/12),0) -> 19149.052 | I40: =$C$29-E40 -> 4044.6744 | J40: =RANK(E40,$E$37:$E$51,1) -> 4
B41: =B10 -> BYD Dolphin Surf | C41: =D10 -> 22990 | D41: =I10 -> 18990 | E41: =(D10+Annahmen!$C$41)-Annahmen!$C$77-Annahmen!$C$17/(1+Annahmen!$C$10)^Annahmen!$C$19-D10*(1-Annahmen!$C$37)^Annahmen!$C$7/(1+Annahmen!$C$9)^Annahmen!$C$7+$C$24*(Annahmen!$C$39+Annahmen!$C$40+Annahmen!$C$42-Annahmen!$C$20)+$C$25*(Annahmen!$C$6/100*F10*Annahmen!$C$27) -> 20339.074 | F41: =E41/$C$24 -> 3754.5421 | G41: =F41/Annahmen!$C$6 -> 0.31287851 | H41: =12*(D10*Annahmen!$C$45/100)*$C$24+Annahmen!$C$49+Annahmen!$C$41-Annahmen!$C$77-Annahmen!$C$17/(1+Annahmen!$C$10)^Annahmen!$C$19+$C$24*(Annahmen!$C$53+Annahmen!$C$54-Annahmen!$C$20)+$C$25*(Annahmen!$C$6/100*F10*Annahmen!$C$27)+Annahmen!$C$52/(1+Annahmen!$C$9)^(Annahmen!$C$47/12)+IF(Annahmen!$C$7>=2*Annahmen!$C$47/12,Annahmen!$C$52/(1+Annahmen!$C$9)^(2*Annahmen!$C$47/12),0) -> 20817.459 | I41: =$C$29-E41 -> 2274.0266 | J41: =RANK(E41,$E$37:$E$51,1) -> 5
B42: =B11 -> Hyundai Inster | C42: =D11 -> 23900 | D42: =I11 -> 19900 | E42: =(D11+Annahmen!$C$41)-Annahmen!$C$77-Annahmen!$C$17/(1+Annahmen!$C$10)^Annahmen!$C$19-D11*(1-Annahmen!$C$37)^Annahmen!$C$7/(1+Annahmen!$C$9)^Annahmen!$C$7+$C$24*(Annahmen!$C$39+Annahmen!$C$40+Annahmen!$C$42-Annahmen!$C$20)+$C$25*(Annahmen!$C$6/100*F11*Annahmen!$C$27) -> 20708.04 | F42: =E42/$C$24 -> 3822.6525 | G42: =F42/Annahmen!$C$6 -> 0.31855437 | H42: =12*(D11*Annahmen!$C$45/100)*$C$24+Annahmen!$C$49+Annahmen!$C$41-Annahmen!$C$77-Annahmen!$C$17/(1+Annahmen!$C$10)^Annahmen!$C$19+$C$24*(Annahmen!$C$53+Annahmen!$C$54-Annahmen!$C$20)+$C$25*(Annahmen!$C$6/100*F11*Annahmen!$C$27)+Annahmen!$C$52/(1+Annahmen!$C$9)^(Annahmen!$C$47/12)+IF(Annahmen!$C$7>=2*Annahmen!$C$47/12,Annahmen!$C$52/(1+Annahmen!$C$9)^(2*Annahmen!$C$47/12),0) -> 21155.413 | I42: =$C$29-E42 -> 1905.0599 | J42: =RANK(E42,$E$37:$E$51,1) -> 6
B43: =B12 -> Fiat Grande Panda | C43: =D12 -> 24990 | D43: =I12 -> 20990 | E43: =(D12+Annahmen!$C$41)-Annahmen!$C$77-Annahmen!$C$17/(1+Annahmen!$C$10)^Annahmen!$C$19-D12*(1-Annahmen!$C$37)^Annahmen!$C$7/(1+Annahmen!$C$9)^Annahmen!$C$7+$C$24*(Annahmen!$C$39+Annahmen!$C$40+Annahmen!$C$42-Annahmen!$C$20)+$C$25*(Annahmen!$C$6/100*F12*Annahmen!$C$27) -> 21989.142 | F43: =E43/$C$24 -> 4059.1406 | G43: =F43/Annahmen!$C$6 -> 0.33826172 | H43: =12*(D12*Annahmen!$C$45/100)*$C$24+Annahmen!$C$49+Annahmen!$C$41-Annahmen!$C$77-Annahmen!$C$17/(1+Annahmen!$C$10)^Annahmen!$C$19+$C$24*(Annahmen!$C$53+Annahmen!$C$54-Annahmen!$C$20)+$C$25*(Annahmen!$C$6/100*F12*Annahmen!$C$27)+Annahmen!$C$52/(1+Annahmen!$C$9)^(Annahmen!$C$47/12)+IF(Annahmen!$C$7>=2*Annahmen!$C$47/12,Annahmen!$C$52/(1+Annahmen!$C$9)^(2*Annahmen!$C$47/12),0) -> 22399.367 | I43: =$C$29-E43 -> 623.95831 | J43: =RANK(E43,$E$37:$E$51,1) -> 8
B44: =B13 -> VW ID.Polo | C44: =D13 -> 24995 | D44: =I13 -> 20995 | E44: =(D13+Annahmen!$C$41)-Annahmen!$C$77-Annahmen!$C$17/(1+Annahmen!$C$10)^Annahmen!$C$19-D13*(1-Annahmen!$C$37)^Annahmen!$C$7/(1+Annahmen!$C$9)^Annahmen!$C$7+$C$24*(Annahmen!$C$39+Annahmen!$C$40+Annahmen!$C$42-Annahmen!$C$20)+$C$25*(Annahmen!$C$6/100*F13*Annahmen!$C$27) -> 21288.108 | F44: =E44/$C$24 -> 3929.7315 | G44: =F44/Annahmen!$C$6 -> 0.32747763 | H44: =12*(D13*Annahmen!$C$45/100)*$C$24+Annahmen!$C$49+Annahmen!$C$41-Annahmen!$C$77-Annahmen!$C$17/(1+Annahmen!$C$10)^Annahmen!$C$19+$C$24*(Annahmen!$C$53+Annahmen!$C$54-Annahmen!$C$20)+$C$25*(Annahmen!$C$6/100*F13*Annahmen!$C$27)+Annahmen!$C$52/(1+Annahmen!$C$9)^(Annahmen!$C$47/12)+IF(Annahmen!$C$7>=2*Annahmen!$C$47/12,Annahmen!$C$52/(1+Annahmen!$C$9)^(2*Annahmen!$C$47/12),0) -> 21698.163 | I44: =$C$29-E44 -> 1324.9921 | J44: =RANK(E44,$E$37:$E$51,1) -> 7
B45: =B14 -> Skoda Epiq | C45: =D14 -> 25900 | D45: =I14 -> 21900 | E45: =(D14+Annahmen!$C$41)-Annahmen!$C$77-Annahmen!$C$17/(1+Annahmen!$C$10)^Annahmen!$C$19-D14*(1-Annahmen!$C$37)^Annahmen!$C$7/(1+Annahmen!$C$9)^Annahmen!$C$7+$C$24*(Annahmen!$C$39+Annahmen!$C$40+Annahmen!$C$42-Annahmen!$C$20)+$C$25*(Annahmen!$C$6/100*F14*Annahmen!$C$27) -> 22189.039 | F45: =E45/$C$24 -> 4096.0412 | G45: =F45/Annahmen!$C$6 -> 0.34133677 | H45: =12*(D14*Annahmen!$C$45/100)*$C$24+Annahmen!$C$49+Annahmen!$C$41-Annahmen!$C$77-Annahmen!$C$17/(1+Annahmen!$C$10)^Annahmen!$C$19+$C$24*(Annahmen!$C$53+Annahmen!$C$54-Annahmen!$C$20)+$C$25*(Annahmen!$C$6/100*F14*Annahmen!$C$27)+Annahmen!$C$52/(1+Annahmen!$C$9)^(Annahmen!$C$47/12)+IF(Annahmen!$C$7>=2*Annahmen!$C$47/12,Annahmen!$C$52/(1+Annahmen!$C$9)^(2*Annahmen!$C$47/12),0) -> 22568.252 | I45: =$C$29-E45 -> 424.06071 | J45: =RANK(E45,$E$37:$E$51,1) -> 9
B46: =B15 -> Renault 5 E-Tech | C46: =D15 -> 28000 | D46: =I15 -> 24000 | E46: =(D15+Annahmen!$C$41)-Annahmen!$C$77-Annahmen!$C$17/(1+Annahmen!$C$10)^Annahmen!$C$19-D15*(1-Annahmen!$C$37)^Annahmen!$C$7/(1+Annahmen!$C$9)^Annahmen!$C$7+$C$24*(Annahmen!$C$39+Annahmen!$C$40+Annahmen!$C$42-Annahmen!$C$20)+$C$25*(Annahmen!$C$6/100*F15*Annahmen!$C$27) -> 23484.849 | F46: =E46/$C$24 -> 4335.2445 | G46: =F46/Annahmen!$C$6 -> 0.36127037 | H46: =12*(D15*Annahmen!$C$45/100)*$C$24+Annahmen!$C$49+Annahmen!$C$41-Annahmen!$C$77-Annahmen!$C$17/(1+Annahmen!$C$10)^Annahmen!$C$19+$C$24*(Annahmen!$C$53+Annahmen!$C$54-Annahmen!$C$20)+$C$25*(Annahmen!$C$6/100*F15*Annahmen!$C$27)+Annahmen!$C$52/(1+Annahmen!$C$9)^(Annahmen!$C$47/12)+IF(Annahmen!$C$7>=2*Annahmen!$C$47/12,Annahmen!$C$52/(1+Annahmen!$C$9)^(2*Annahmen!$C$47/12),0) -> 23792.493 | I46: =$C$29-E46 -> -871.74913 | J46: =RANK(E46,$E$37:$E$51,1) -> 10
B47: =B16 -> Opel Frontera Electric | C47: =D16 -> 28990 | D47: =I16 -> 24990 | E47: =(D16+Annahmen!$C$41)-Annahmen!$C$77-Annahmen!$C$17/(1+Annahmen!$C$10)^Annahmen!$C$19-D16*(1-Annahmen!$C$37)^Annahmen!$C$7/(1+Annahmen!$C$9)^Annahmen!$C$7+$C$24*(Annahmen!$C$39+Annahmen!$C$40+Annahmen!$C$42-Annahmen!$C$20)+$C$25*(Annahmen!$C$6/100*F16*Annahmen!$C$27) -> 25148.387 | F47: =E47/$C$24 -> 4642.3295 | G47: =F47/Annahmen!$C$6 -> 0.38686079 | H47: =12*(D16*Annahmen!$C$45/100)*$C$24+Annahmen!$C$49+Annahmen!$C$41-Annahmen!$C$77-Annahmen!$C$17/(1+Annahmen!$C$10)^Annahmen!$C$19+$C$24*(Annahmen!$C$53+Annahmen!$C$54-Annahmen!$C$20)+$C$25*(Annahmen!$C$6/100*F16*Annahmen!$C$27)+Annahmen!$C$52/(1+Annahmen!$C$9)^(Annahmen!$C$47/12)+IF(Annahmen!$C$7>=2*Annahmen!$C$47/12,Annahmen!$C$52/(1+Annahmen!$C$9)^(2*Annahmen!$C$47/12),0) -> 25422.292 | I47: =$C$29-E47 -> -2535.2873 | J47: =RANK(E47,$E$37:$E$51,1) -> 11
B48: =B17 -> Hyundai Ioniq 3 | C48: =D17 -> 35000 | D48: =I17 -> 31000 | E48: =(D17+Annahmen!$C$41)-Annahmen!$C$77-Annahmen!$C$17/(1+Annahmen!$C$10)^Annahmen!$C$19-D17*(1-Annahmen!$C$37)^Annahmen!$C$7/(1+Annahmen!$C$9)^Annahmen!$C$7+$C$24*(Annahmen!$C$39+Annahmen!$C$40+Annahmen!$C$42-Annahmen!$C$20)+$C$25*(Annahmen!$C$6/100*F17*Annahmen!$C$27) -> 28132.961 | F48: =E48/$C$24 -> 5193.2743 | G48: =F48/Annahmen!$C$6 -> 0.43277285 | H48: =12*(D17*Annahmen!$C$45/100)*$C$24+Annahmen!$C$49+Annahmen!$C$41-Annahmen!$C$77-Annahmen!$C$17/(1+Annahmen!$C$10)^Annahmen!$C$19+$C$24*(Annahmen!$C$53+Annahmen!$C$54-Annahmen!$C$20)+$C$25*(Annahmen!$C$6/100*F17*Annahmen!$C$27)+Annahmen!$C$52/(1+Annahmen!$C$9)^(Annahmen!$C$47/12)+IF(Annahmen!$C$7>=2*Annahmen!$C$47/12,Annahmen!$C$52/(1+Annahmen!$C$9)^(2*Annahmen!$C$47/12),0) -> 28202.043 | I48: =$C$29-E48 -> -5519.8608 | J48: =RANK(E48,$E$37:$E$51,1) -> 12
... B51: =B20 -> Kia EV3 LR (81 kWh) | C51: =D20 -> 43890 | D51: =I20 -> 39890 | E51: =(D20+Annahmen!$C$41)-Annahmen!$C$77-Annahmen!$C$17/(1+Annahmen!$C$10)^Annahmen!$C$19-D20*(1-Annahmen!$C$37)^Annahmen!$C$7/(1+Annahmen!$C$9)^Annahmen!$C$7+$C$24*(Annahmen!$C$39+Annahmen!$C$40+Annahmen!$C$42-Annahmen!$C$20)+$C$25*(Annahmen!$C$6/100*F20*Annahmen!$C$27) -> 34637.667 | F51: =E51/$C$24 -> 6394.0267 | G51: =F51/Annahmen!$C$6 -> 0.53283556 | H51: =12*(D20*Annahmen!$C$45/100)*$C$24+Annahmen!$C$49+Annahmen!$C$41-Annahmen!$C$77-Annahmen!$C$17/(1+Annahmen!$C$10)^Annahmen!$C$19+$C$24*(Annahmen!$C$53+Annahmen!$C$54-Annahmen!$C$20)+$C$25*(Annahmen!$C$6/100*F20*Annahmen!$C$27)+Annahmen!$C$52/(1+Annahmen!$C$9)^(Annahmen!$C$47/12)+IF(Annahmen!$C$7>=2*Annahmen!$C$47/12,Annahmen!$C$52/(1+Annahmen!$C$9)^(2*Annahmen!$C$47/12),0) -> 34403.776 | I51: =$C$29-E51 -> -12024.567 | J51: =RANK(E51,$E$37:$E$51,1) -> 15
B52: A4 Status quo: Bestand reparieren + Ersatz in n Jahren | E52: =$C$29 -> 22613.1 | F52: =E52/$C$24 -> 4174.3218 | G52: =F52/Annahmen!$C$6 -> 0.34786015 | I52: 0
...

Sheet Cashflow
B2: Monatliche Zahlungsreihen der vier Handlungsalternativen
B3: Negativ = Auszahlung, positiv = Einzahlung (Förderung, THG, Restwert, Verkaufserlös). In A4 findet im Monat der Restnutzungsdauer der Fahrzeugtausch statt.
B5: Monat | C5: Diskont- faktor | D5: Energie- preisindex | E5: A1 E-Auto kaufen | F5: A2 E-Auto leasen | G5: A3 Verbrenner neu kaufen | H5: A4 Bestand + Ersatzbeschaffung | I5: A5 gebrauchtes E-Auto kaufen
B6: 0 | C6: =1/(1+Annahmen!$C$10)^$B6 -> 1 | D6: =(1+Annahmen!$C$11)^INT(MAX($B6-1,0)/12) -> 1 | E6: =IF($B6>Annahmen!$C$8,0,IF($B6=0,-(Annahmen!$C$33+Annahmen!$C$41)+Annahmen!$C$77,-Annahmen!$C$6/12/100*Annahmen!$C$36*Annahmen!$C$27*$D6-(Annahmen!$C$39+Annahmen!$C$40+Annahmen!$C$42)/12+IF($B6=Annahmen!$C$19,Annahmen!$C$17,0)+IF(MOD($B6,12)=0,Annahmen!$C$20,0)+IF($B6=Annahmen!$C$8,Annahmen!$C$38,0))) -> -23900 | F6: =IF($B6>Annahmen!$C$8,0,IF($B6=0,-(Annahmen!$C$49+Annahmen!$C$41)+Annahmen!$C$77,-Annahmen!$C$46*(1+Annahmen!$C$48)^INT(($B6-1)/Annahmen!$C$47)-Annahmen!$C$6/12/100*Annahmen!$C$36*Annahmen!$C$27*$D6-(Annahmen!$C$53+Annahmen!$C$54)/12+IF($B6=Annahmen!$C$19,Annahmen!$C$17,0)+IF(MOD($B6,12)=0,Annahmen!$C$20,0)-IF(MOD($B6,Annahmen!$C$47)=0,Annahmen!$C$52,0)-IF(AND(MOD($B6,Annahmen!$C$47)=0,$B6<Annahmen!$C$8),Annahmen!$C$49*(1+Annahmen!$C$48)^($B6/Annahmen!$C$47),0))) -> 0 | G6: =IF($B6>Annahmen!$C$8,0,IF($B6=0,-Annahmen!$C$57+Annahmen!$C$77,-Annahmen!$C$6/12/100*Annahmen!$C$58*Annahmen!$C$28*$D6-(Annahmen!$C$61+Annahmen!$C$62+Annahmen!$C$63)/12+IF($B6=Annahmen!$C$8,Annahmen!$C$60,0))) -> -20500 | H6: =IF($B6>Annahmen!$C$8,0,IF($B6=0,-Annahmen!$C$66,IF($B6<=Annahmen!$C$67*12,-Annahmen!$C$6/12/100*Annahmen!$C$72*$D6-(Annahmen!$C$73+Annahmen!$C$74+Annahmen!$C$75)/12+IF($B6=Annahmen!$C$67*12,Annahmen!$C$76-(Annahmen!$C$81+Annahmen!$C$41),0),-Annahmen!$C$6/12/100*Annahmen!$C$36*Annahmen!$C$27*$D6-(Annahmen!$C$39+Annahmen!$C$40+Annahmen!$C$42)/12+IF(MOD($B6,12)=0,Annahmen!$C$20,0)+IF($B6=Annahmen!$C$8,Annahmen!$C$82,0))+IF($B6=Annahmen!$C$67*12+Annahmen!$C$19,Annahmen!$C$17*Annahmen!$C$21,0))) -> -2500 | I6: =IF($B6>Annahmen!$C$8,0,IF($B6=0,-(Annahmen!$C$86+Annahmen!$C$41)+Annahmen!$C$77,-Annahmen!$C$6/12/100*Annahmen!$C$89*Annahmen!$C$27*$D6-(Annahmen!$C$92+Annahmen!$C$93+Annahmen!$C$94+Annahmen!$C$95)/12+IF(MOD($B6,12)=0,Annahmen!$C$20,0)+IF($B6=Annahmen!$C$8,Annahmen!$C$91,0))) -> -18000
B7: 1 | C7: =1/(1+Annahmen!$C$10)^$B7 -> 0.9975398 | D7: =(1+Annahmen!$C$11)^INT(MAX($B7-1,0)/12) -> 1 | E7: =IF($B7>Annahmen!$C$8,0,IF($B7=0,-(Annahmen!$C$33+Annahmen!$C$41)+Annahmen!$C$77,-Annahmen!$C$6/12/100*Annahmen!$C$36*Annahmen!$C$27*$D7-(Annahmen!$C$39+Annahmen!$C$40+Annahmen!$C$42)/12+IF($B7=Annahmen!$C$19,Annahmen!$C$17,0)+IF(MOD($B7,12)=0,Annahmen!$C$20,0)+IF($B7=Annahmen!$C$8,Annahmen!$C$38,0))) -> -149.863 | F7: =IF($B7>Annahmen!$C$8,0,IF($B7=0,-(Annahmen!$C$49+Annahmen!$C$41)+Annahmen!$C$77,-Annahmen!$C$46*(1+Annahmen!$C$48)^INT(($B7-1)/Annahmen!$C$47)-Annahmen!$C$6/12/100*Annahmen!$C$36*Annahmen!$C$27*$D7-(Annahmen!$C$53+Annahmen!$C$54)/12+IF($B7=Annahmen!$C$19,Annahmen!$C$17,0)+IF(MOD($B7,12)=0,Annahmen!$C$20,0)-IF(MOD($B7,Annahmen!$C$47)=0,Annahmen!$C$52,0)-IF(AND(MOD($B7,Annahmen!$C$47)=0,$B7<Annahmen!$C$8),Annahmen!$C$49*(1+Annahmen!$C$48)^($B7/Annahmen!$C$47),0))) -> -388.863 | G7: =IF($B7>Annahmen!$C$8,0,IF($B7=0,-Annahmen!$C$57+Annahmen!$C$77,-Annahmen!$C$6/12/100*Annahmen!$C$58*Annahmen!$C$28*$D7-(Annahmen!$C$61+Annahmen!$C$62+Annahmen!$C$63)/12+IF($B7=Annahmen!$C$8,Annahmen!$C$60,0))) -> -238.5 | H7: =IF($B7>Annahmen!$C$8,0,IF($B7=0,-Annahmen!$C$66,IF($B7<=Annahmen!$C$67*12,-Annahmen!$C$6/12/100*Annahmen!$C$72*$D7-(Annahmen!$C$73+Annahmen!$C$74+Annahmen!$C$75)/12+IF($B7=Annahmen!$C$67*12,Annahmen!$C$76-(Annahmen!$C$81+Annahmen!$C$41),0),-Annahmen!$C$6/12/100*Annahmen!$C$36*Annahmen!$C$27*$D7-(Annahmen!$C$39+Annahmen!$C$40+Annahmen!$C$42)/12+IF(MOD($B7,12)=0,Annahmen!$C$20,0)+IF($B7=Annahmen!$C$8,Annahmen!$C$82,0))+IF($B7=Annahmen!$C$67*12+Annahmen!$C$19,Annahmen!$C$17*Annahmen!$C$21,0))) -> -230.10667 | I7: =IF($B7>Annahmen!$C$8,0,IF($B7=0,-(Annahmen!$C$86+Annahmen!$C$41)+Annahmen!$C$77,-Annahmen!$C$6/12/100*Annahmen!$C$89*Annahmen!$C$27*$D7-(Annahmen!$C$92+Annahmen!$C$93+Annahmen!$C$94+Annahmen!$C$95)/12+IF(MOD($B7,12)=0,Annahmen!$C$20,0)+IF($B7=Annahmen!$C$8,Annahmen!$C$91,0))) -> -195.24667
B8: 2 | C8: =1/(1+Annahmen!$C$10)^$B8 -> 0.99508565 | D8: =(1+Annahmen!$C$11)^INT(MAX($B8-1,0)/12) -> 1 | E8: =IF($B8>Annahmen!$C$8,0,IF($B8=0,-(Annahmen!$C$33+Annahmen!$C$41)+Annahmen!$C$77,-Annahmen!$C$6/12/100*Annahmen!$C$36*Annahmen!$C$27*$D8-(Annahmen!$C$39+Annahmen!$C$40+Annahmen!$C$42)/12+IF($B8=Annahmen!$C$19,Annahmen!$C$17,0)+IF(MOD($B8,12)=0,Annahmen!$C$20,0)+IF($B8=Annahmen!$C$8,Annahmen!$C$38,0))) -> -149.863 | F8: =IF($B8>Annahmen!$C$8,0,IF($B8=0,-(Annahmen!$C$49+Annahmen!$C$41)+Annahmen!$C$77,-Annahmen!$C$46*(1+Annahmen!$C$48)^INT(($B8-1)/Annahmen!$C$47)-Annahmen!$C$6/12/100*Annahmen!$C$36*Annahmen!$C$27*$D8-(Annahmen!$C$53+Annahmen!$C$54)/12+IF($B8=Annahmen!$C$19,Annahmen!$C$17,0)+IF(MOD($B8,12)=0,Annahmen!$C$20,0)-IF(MOD($B8,Annahmen!$C$47)=0,Annahmen!$C$52,0)-IF(AND(MOD($B8,Annahmen!$C$47)=0,$B8<Annahmen!$C$8),Annahmen!$C$49*(1+Annahmen!$C$48)^($B8/Annahmen!$C$47),0))) -> -388.863 | G8: =IF($B8>Annahmen!$C$8,0,IF($B8=0,-Annahmen!$C$57+Annahmen!$C$77,-Annahmen!$C$6/12/100*Annahmen!$C$58*Annahmen!$C$28*$D8-(Annahmen!$C$61+Annahmen!$C$62+Annahmen!$C$63)/12+IF($B8=Annahmen!$C$8,Annahmen!$C$60,0))) -> -238.5 | H8: =IF($B8>Annahmen!$C$8,0,IF($B8=0,-Annahmen!$C$66,IF($B8<=Annahmen!$C$67*12,-Annahmen!$C$6/12/100*Annahmen!$C$72*$D8-(Annahmen!$C$73+Annahmen!$C$74+Annahmen!$C$75)/12+IF($B8=Annahmen!$C$67*12,Annahmen!$C$76-(Annahmen!$C$81+Annahmen!$C$41),0),-Annahmen!$C$6/12/100*Annahmen!$C$36*Annahmen!$C$27*$D8-(Annahmen!$C$39+Annahmen!$C$40+Annahmen!$C$42)/12+IF(MOD($B8,12)=0,Annahmen!$C$20,0)+IF($B8=Annahmen!$C$8,Annahmen!$C$82,0))+IF($B8=Annahmen!$C$67*12+Annahmen!$C$19,Annahmen!$C$17*Annahmen!$C$21,0))) -> -230.10667 | I8: =IF($B8>Annahmen!$C$8,0,IF($B8=0,-(Annahmen!$C$86+Annahmen!$C$41)+Annahmen!$C$77,-Annahmen!$C$6/12/100*Annahmen!$C$89*Annahmen!$C$27*$D8-(Annahmen!$C$92+Annahmen!$C$93+Annahmen!$C$94+Annahmen!$C$95)/12+IF(MOD($B8,12)=0,Annahmen!$C$20,0)+IF($B8=Annahmen!$C$8,Annahmen!$C$91,0))) -> -195.24667
B9: 3 | C9: =1/(1+Annahmen!$C$10)^$B9 -> 0.99263754 | D9: =(1+Annahmen!$C$11)^INT(MAX($B9-1,0)/12) -> 1 | E9: =IF($B9>Annahmen!$C$8,0,IF($B9=0,-(Annahmen!$C$33+Annahmen!$C$41)+Annahmen!$C$77,-Annahmen!$C$6/12/100*Annahmen!$C$36*Annahmen!$C$27*$D9-(Annahmen!$C$39+Annahmen!$C$40+Annahmen!$C$42)/12+IF($B9=Annahmen!$C$19,Annahmen!$C$17,0)+IF(MOD($B9,12)=0,Annahmen!$C$20,0)+IF($B9=Annahmen!$C$8,Annahmen!$C$38,0))) -> -149.863 | F9: =IF($B9>Annahmen!$C$8,0,IF($B9=0,-(Annahmen!$C$49+Annahmen!$C$41)+Annahmen!$C$77,-Annahmen!$C$46*(1+Annahmen!$C$48)^INT(($B9-1)/Annahmen!$C$47)-Annahmen!$C$6/12/100*Annahmen!$C$36*Annahmen!$C$27*$D9-(Annahmen!$C$53+Annahmen!$C$54)/12+IF($B9=Annahmen!$C$19,Annahmen!$C$17,0)+IF(MOD($B9,12)=0,Annahmen!$C$20,0)-IF(MOD($B9,Annahmen!$C$47)=0,Annahmen!$C$52,0)-IF(AND(MOD($B9,Annahmen!$C$47)=0,$B9<Annahmen!$C$8),Annahmen!$C$49*(1+Annahmen!$C$48)^($B9/Annahmen!$C$47),0))) -> -388.863 | G9: =IF($B9>Annahmen!$C$8,0,IF($B9=0,-Annahmen!$C$57+Annahmen!$C$77,-Annahmen!$C$6/12/100*Annahmen!$C$58*Annahmen!$C$28*$D9-(Annahmen!$C$61+Annahmen!$C$62+Annahmen!$C$63)/12+IF($B9=Annahmen!$C$8,Annahmen!$C$60,0))) -> -238.5 | H9: =IF($B9>Annahmen!$C$8,0,IF($B9=0,-Annahmen!$C$66,IF($B9<=Annahmen!$C$67*12,-Annahmen!$C$6/12/100*Annahmen!$C$72*$D9-(Annahmen!$C$73+Annahmen!$C$74+Annahmen!$C$75)/12+IF($B9=Annahmen!$C$67*12,Annahmen!$C$76-(Annahmen!$C$81+Annahmen!$C$41),0),-Annahmen!$C$6/12/100*Annahmen!$C$36*Annahmen!$C$27*$D9-(Annahmen!$C$39+Annahmen!$C$40+Annahmen!$C$42)/12+IF(MOD($B9,12)=0,Annahmen!$C$20,0)+IF($B9=Annahmen!$C$8,Annahmen!$C$82,0))+IF($B9=Annahmen!$C$67*12+Annahmen!$C$19,Annahmen!$C$17*Annahmen!$C$21,0))) -> -230.10667 | I9: =IF($B9>Annahmen!$C$8,0,IF($B9=0,-(Annahmen!$C$86+Annahmen!$C$41)+Annahmen!$C$77,-Annahmen!$C$6/12/100*Annahmen!$C$89*Annahmen!$C$27*$D9-(Annahmen!$C$92+Annahmen!$C$93+Annahmen!$C$94+Annahmen!$C$95)/12+IF(MOD($B9,12)=0,Annahmen!$C$20,0)+IF($B9=Annahmen!$C$8,Annahmen!$C$91,0))) -> -195.24667
B10: 4 | C10: =1/(1+Annahmen!$C$10)^$B10 -> 0.99019545 | D10: =(1+Annahmen!$C$11)^INT(MAX($B10-1,0)/12) -> 1 | E10: =IF($B10>Annahmen!$C$8,0,IF($B10=0,-(Annahmen!$C$33+Annahmen!$C$41)+Annahmen!$C$77,-Annahmen!$C$6/12/100*Annahmen!$C$36*Annahmen!$C$27*$D10-(Annahmen!$C$39+Annahmen!$C$40+Annahmen!$C$42)/12+IF($B10=Annahmen!$C$19,Annahmen!$C$17,0)+IF(MOD($B10,12)=0,Annahmen!$C$20,0)+IF($B10=Annahmen!$C$8,Annahmen!$C$38,0))) -> 3850.137 | F10: =IF($B10>Annahmen!$C$8,0,IF($B10=0,-(Annahmen!$C$49+Annahmen!$C$41)+Annahmen!$C$77,-Annahmen!$C$46*(1+Annahmen!$C$48)^INT(($B10-1)/Annahmen!$C$47)-Annahmen!$C$6/12/100*Annahmen!$C$36*Annahmen!$C$27*$D10-(Annahmen!$C$53+Annahmen!$C$54)/12+IF($B10=Annahmen!$C$19,Annahmen!$C$17,0)+IF(MOD($B10,12)=0,Annahmen!$C$20,0)-IF(MOD($B10,Annahmen!$C$47)=0,Annahmen!$C$52,0)-IF(AND(MOD($B10,Annahmen!$C$47)=0,$B10<Annahmen!$C$8),Annahmen!$C$49*(1+Annahmen!$C$48)^($B10/Annahmen!$C$47),0))) -> 3611.137 | G10: =IF($B10>Annahmen!$C$8,0,IF($B10=0,-Annahmen!$C$57+Annahmen!$C$77,-Annahmen!$C$6/12/100*Annahmen!$C$58*Annahmen!$C$28*$D10-(Annahmen!$C$61+Annahmen!$C$62+Annahmen!$C$63)/12+IF($B10=Annahmen!$C$8,Annahmen!$C$60,0))) -> -238.5 | H10: =IF($B10>Annahmen!$C$8,0,IF($B10=0,-Annahmen!$C$66,IF($B10<=Annahmen!$C$67*12,-Annahmen!$C$6/12/100*Annahmen!$C$72*$D10-(Annahmen!$C$73+Annahmen!$C$74+Annahmen!$C$75)/12+IF($B10=Annahmen!$C$67*12,Annahmen!$C$76-(Annahmen!$C$81+Annahmen!$C$41),0),-Annahmen!$C$6/12/100*Annahmen!$C$36*Annahmen!$C$27*$D10-(Annahmen!$C$39+Annahmen!$C$40+Annahmen!$C$42)/12+IF(MOD($B10,12)=0,Annahmen!$C$20,0)+IF($B10=Annahmen!$C$8,Annahmen!$C$82,0))+IF($B10=Annahmen!$C$67*12+Annahmen!$C$19,Annahmen!$C$17*Annahmen!$C$21,0))) -> -230.10667 | I10: =IF($B10>Annahmen!$C$8,0,IF($B10=0,-(Annahmen!$C$86+Annahmen!$C$41)+Annahmen!$C$77,-Annahmen!$C$6/12/100*Annahmen!$C$89*Annahmen!$C$27*$D10-(Annahmen!$C$92+Annahmen!$C$93+Annahmen!$C$94+Annahmen!$C$95)/12+IF(MOD($B10,12)=0,Annahmen!$C$20,0)+IF($B10=Annahmen!$C$8,Annahmen!$C$91,0))) -> -195.24667
B11: 5 | C11: =1/(1+Annahmen!$C$10)^$B11 -> 0.98775937 | D11: =(1+Annahmen!$C$11)^INT(MAX($B11-1,0)/12) -> 1 | E11: =IF($B11>Annahmen!$C$8,0,IF($B11=0,-(Annahmen!$C$33+Annahmen!$C$41)+Annahmen!$C$77,-Annahmen!$C$6/12/100*Annahmen!$C$36*Annahmen!$C$27*$D11-(Annahmen!$C$39+Annahmen!$C$40+Annahmen!$C$42)/12+IF($B11=Annahmen!$C$19,Annahmen!$C$17,0)+IF(MOD($B11,12)=0,Annahmen!$C$20,0)+IF($B11=Annahmen!$C$8,Annahmen!$C$38,0))) -> -149.863 | F11: =IF($B11>Annahmen!$C$8,0,IF($B11=0,-(Annahmen!$C$49+Annahmen!$C$41)+Annahmen!$C$77,-Annahmen!$C$46*(1+Annahmen!$C$48)^INT(($B11-1)/Annahmen!$C$47)-Annahmen!$C$6/12/100*Annahmen!$C$36*Annahmen!$C$27*$D11-(Annahmen!$C$53+Annahmen!$C$54)/12+IF($B11=Annahmen!$C$19,Annahmen!$C$17,0)+IF(MOD($B11,12)=0,Annahmen!$C$20,0)-IF(MOD($B11,Annahmen!$C$47)=0,Annahmen!$C$52,0)-IF(AND(MOD($B11,Annahmen!$C$47)=0,$B11<Annahmen!$C$8),Annahmen!$C$49*(1+Annahmen!$C$48)^($B11/Annahmen!$C$47),0))) -> -388.863 | G11: =IF($B11>Annahmen!$C$8,0,IF($B11=0,-Annahmen!$C$57+Annahmen!$C$77,-Annahmen!$C$6/12/100*Annahmen!$C$58*Annahmen!$C$28*$D11-(Annahmen!$C$61+Annahmen!$C$62+Annahmen!$C$63)/12+IF($B11=Annahmen!$C$8,Annahmen!$C$60,0))) -> -238.5 | H11: =IF($B11>Annahmen!$C$8,0,IF($B11=0,-Annahmen!$C$66,IF($B11<=Annahmen!$C$67*12,-Annahmen!$C$6/12/100*Annahmen!$C$72*$D11-(Annahmen!$C$73+Annahmen!$C$74+Annahmen!$C$75)/12+IF($B11=Annahmen!$C$67*12,Annahmen!$C$76-(Annahmen!$C$81+Annahmen!$C$41),0),-Annahmen!$C$6/12/100*Annahmen!$C$36*Annahmen!$C$27*$D11-(Annahmen!$C$39+Annahmen!$C$40+Annahmen!$C$42)/12+IF(MOD($B11,12)=0,Annahmen!$C$20,0)+IF($B11=Annahmen!$C$8,Annahmen!$C$82,0))+IF($B11=Annahmen!$C$67*12+Annahmen!$C$19,Annahmen!$C$17*Annahmen!$C$21,0))) -> -230.10667 | I11: =IF($B11>Annahmen!$C$8,0,IF($B11=0,-(Annahmen!$C$86+Annahmen!$C$41)+Annahmen!$C$77,-Annahmen!$C$6/12/100*Annahmen!$C$89*Annahmen!$C$27*$D11-(Annahmen!$C$92+Annahmen!$C$93+Annahmen!$C$94+Annahmen!$C$95)/12+IF(MOD($B11,12)=0,Annahmen!$C$20,0)+IF($B11=Annahmen!$C$8,Annahmen!$C$91,0))) -> -195.24667
B12: 6 | C12: =1/(1+Annahmen!$C$10)^$B12 -> 0.98532928 | D12: =(1+Annahmen!$C$11)^INT(MAX($B12-1,0)/12) -> 1 | E12: =IF($B12>Annahmen!$C$8,0,IF($B12=0,-(Annahmen!$C$33+Annahmen!$C$41)+Annahmen!$C$77,-Annahmen!$C$6/12/100*Annahmen!$C$36*Annahmen!$C$27*$D12-(Annahmen!$C$39+Annahmen!$C$40+Annahmen!$C$42)/12+IF($B12=Annahmen!$C$19,Annahmen!$C$17,0)+IF(MOD($B12,12)=0,Annahmen!$C$20,0)+IF($B12=Annahmen!$C$8,Annahmen!$C$38,0))) -> -149.863 | F12: =IF($B12>Annahmen!$C$8,0,IF($B12=0,-(Annahmen!$C$49+Annahmen!$C$41)+Annahmen!$C$77,-Annahmen!$C$46*(1+Annahmen!$C$48)^INT(($B12-1)/Annahmen!$C$47)-Annahmen!$C$6/12/100*Annahmen!$C$36*Annahmen!$C$27*$D12-(Annahmen!$C$53+Annahmen!$C$54)/12+IF($B12=Annahmen!$C$19,Annahmen!$C$17,0)+IF(MOD($B12,12)=0,Annahmen!$C$20,0)-IF(MOD($B12,Annahmen!$C$47)=0,Annahmen!$C$52,0)-IF(AND(MOD($B12,Annahmen!$C$47)=0,$B12<Annahmen!$C$8),Annahmen!$C$49*(1+Annahmen!$C$48)^($B12/Annahmen!$C$47),0))) -> -388.863 | G12: =IF($B12>Annahmen!$C$8,0,IF($B12=0,-Annahmen!$C$57+Annahmen!$C$77,-Annahmen!$C$6/12/100*Annahmen!$C$58*Annahmen!$C$28*$D12-(Annahmen!$C$61+Annahmen!$C$62+Annahmen!$C$63)/12+IF($B12=Annahmen!$C$8,Annahmen!$C$60,0))) -> -238.5 | H12: =IF($B12>Annahmen!$C$8,0,IF($B12=0,-Annahmen!$C$66,IF($B12<=Annahmen!$C$67*12,-Annahmen!$C$6/12/100*Annahmen!$C$72*$D12-(Annahmen!$C$73+Annahmen!$C$74+Annahmen!$C$75)/12+IF($B12=Annahmen!$C$67*12,Annahmen!$C$76-(Annahmen!$C$81+Annahmen!$C$41),0),-Annahmen!$C$6/12/100*Annahmen!$C$36*Annahmen!$C$27*$D12-(Annahmen!$C$39+Annahmen!$C$40+Annahmen!$C$42)/12+IF(MOD($B12,12)=0,Annahmen!$C$20,0)+IF($B12=Annahmen!$C$8,Annahmen!$C$82,0))+IF($B12=Annahmen!$C$67*12+Annahmen!$C$19,Annahmen!$C$17*Annahmen!$C$21,0))) -> -230.10667 | I12: =IF($B12>Annahmen!$C$8,0,IF($B12=0,-(Annahmen!$C$86+Annahmen!$C$41)+Annahmen!$C$77,-Annahmen!$C$6/12/100*Annahmen!$C$89*Annahmen!$C$27*$D12-(Annahmen!$C$92+Annahmen!$C$93+Annahmen!$C$94+Annahmen!$C$95)/12+IF(MOD($B12,12)=0,Annahmen!$C$20,0)+IF($B12=Annahmen!$C$8,Annahmen!$C$91,0))) -> -195.24667
B13: 7 | C13: =1/(1+Annahmen!$C$10)^$B13 -> 0.98290517 | D13: =(1+Annahmen!$C$11)^INT(MAX($B13-1,0)/12) -> 1 | E13: =IF($B13>Annahmen!$C$8,0,IF($B13=0,-(Annahmen!$C$33+Annahmen!$C$41)+Annahmen!$C$77,-Annahmen!$C$6/12/100*Annahmen!$C$36*Annahmen!$C$27*$D13-(Annahmen!$C$39+Annahmen!$C$40+Annahmen!$C$42)/12+IF($B13=Annahmen!$C$19,Annahmen!$C$17,0)+IF(MOD($B13,12)=0,Annahmen!$C$20,0)+IF($B13=Annahmen!$C$8,Annahmen!$C$38,0))) -> -149.863 | F13: =IF($B13>Annahmen!$C$8,0,IF($B13=0,-(Annahmen!$C$49+Annahmen!$C$41)+Annahmen!$C$77,-Annahmen!$C$46*(1+Annahmen!$C$48)^INT(($B13-1)/Annahmen!$C$47)-Annahmen!$C$6/12/100*Annahmen!$C$36*Annahmen!$C$27*$D13-(Annahmen!$C$53+Annahmen!$C$54)/12+IF($B13=Annahmen!$C$19,Annahmen!$C$17,0)+IF(MOD($B13,12)=0,Annahmen!$C$20,0)-IF(MOD($B13,Annahmen!$C$47)=0,Annahmen!$C$52,0)-IF(AND(MOD($B13,Annahmen!$C$47)=0,$B13<Annahmen!$C$8),Annahmen!$C$49*(1+Annahmen!$C$48)^($B13/Annahmen!$C$47),0))) -> -388.863 | G13: =IF($B13>Annahmen!$C$8,0,IF($B13=0,-Annahmen!$C$57+Annahmen!$C$77,-Annahmen!$C$6/12/100*Annahmen!$C$58*Annahmen!$C$28*$D13-(Annahmen!$C$61+Annahmen!$C$62+Annahmen!$C$63)/12+IF($B13=Annahmen!$C$8,Annahmen!$C$60,0))) -> -238.5 | H13: =IF($B13>Annahmen!$C$8,0,IF($B13=0,-Annahmen!$C$66,IF($B13<=Annahmen!$C$67*12,-Annahmen!$C$6/12/100*Annahmen!$C$72*$D13-(Annahmen!$C$73+Annahmen!$C$74+Annahmen!$C$75)/12+IF($B13=Annahmen!$C$67*12,Annahmen!$C$76-(Annahmen!$C$81+Annahmen!$C$41),0),-Annahmen!$C$6/12/100*Annahmen!$C$36*Annahmen!$C$27*$D13-(Annahmen!$C$39+Annahmen!$C$40+Annahmen!$C$42)/12+IF(MOD($B13,12)=0,Annahmen!$C$20,0)+IF($B13=Annahmen!$C$8,Annahmen!$C$82,0))+IF($B13=Annahmen!$C$67*12+Annahmen!$C$19,Annahmen!$C$17*Annahmen!$C$21,0))) -> -230.10667 | I13: =IF($B13>Annahmen!$C$8,0,IF($B13=0,-(Annahmen!$C$86+Annahmen!$C$41)+Annahmen!$C$77,-Annahmen!$C$6/12/100*Annahmen!$C$89*Annahmen!$C$27*$D13-(Annahmen!$C$92+Annahmen!$C$93+Annahmen!$C$94+Annahmen!$C$95)/12+IF(MOD($B13,12)=0,Annahmen!$C$20,0)+IF($B13=Annahmen!$C$8,Annahmen!$C$91,0))) -> -195.24667
B14: 8 | C14: =1/(1+Annahmen!$C$10)^$B14 -> 0.98048702 | D14: =(1+Annahmen!$C$11)^INT(MAX($B14-1,0)/12) -> 1 | E14: =IF($B14>Annahmen!$C$8,0,IF($B14=0,-(Annahmen!$C$33+Annahmen!$C$41)+Annahmen!$C$77,-Annahmen!$C$6/12/100*Annahmen!$C$36*Annahmen!$C$27*$D14-(Annahmen!$C$39+Annahmen!$C$40+Annahmen!$C$42)/12+IF($B14=Annahmen!$C$19,Annahmen!$C$17,0)+IF(MOD($B14,12)=0,Annahmen!$C$20,0)+IF($B14=Annahmen!$C$8,Annahmen!$C$38,0))) -> -149.863 | F14: =IF($B14>Annahmen!$C$8,0,IF($B14=0,-(Annahmen!$C$49+Annahmen!$C$41)+Annahmen!$C$77,-Annahmen!$C$46*(1+Annahmen!$C$48)^INT(($B14-1)/Annahmen!$C$47)-Annahmen!$C$6/12/100*Annahmen!$C$36*Annahmen!$C$27*$D14-(Annahmen!$C$53+Annahmen!$C$54)/12+IF($B14=Annahmen!$C$19,Annahmen!$C$17,0)+IF(MOD($B14,12)=0,Annahmen!$C$20,0)-IF(MOD($B14,Annahmen!$C$47)=0,Annahmen!$C$52,0)-IF(AND(MOD($B14,Annahmen!$C$47)=0,$B14<Annahmen!$C$8),Annahmen!$C$49*(1+Annahmen!$C$48)^($B14/Annahmen!$C$47),0))) -> -388.863 | G14: =IF($B14>Annahmen!$C$8,0,IF($B14=0,-Annahmen!$C$57+Annahmen!$C$77,-Annahmen!$C$6/12/100*Annahmen!$C$58*Annahmen!$C$28*$D14-(Annahmen!$C$61+Annahmen!$C$62+Annahmen!$C$63)/12+IF($B14=Annahmen!$C$8,Annahmen!$C$60,0))) -> -238.5 | H14: =IF($B14>Annahmen!$C$8,0,IF($B14=0,-Annahmen!$C$66,IF($B14<=Annahmen!$C$67*12,-Annahmen!$C$6/12/100*Annahmen!$C$72*$D14-(Annahmen!$C$73+Annahmen!$C$74+Annahmen!$C$75)/12+IF($B14=Annahmen!$C$67*12,Annahmen!$C$76-(Annahmen!$C$81+Annahmen!$C$41),0),-Annahmen!$C$6/12/100*Annahmen!$C$36*Annahmen!$C$27*$D14-(Annahmen!$C$39+Annahmen!$C$40+Annahmen!$C$42)/12+IF(MOD($B14,12)=0,Annahmen!$C$20,0)+IF($B14=Annahmen!$C$8,Annahmen!$C$82,0))+IF($B14=Annahmen!$C$67*12+Annahmen!$C$19,Annahmen!$C$17*Annahmen!$C$21,0))) -> -230.10667 | I14: =IF($B14>Annahmen!$C$8,0,IF($B14=0,-(Annahmen!$C$86+Annahmen!$C$41)+Annahmen!$C$77,-Annahmen!$C$6/12/100*Annahmen!$C$89*Annahmen!$C$27*$D14-(Annahmen!$C$92+Annahmen!$C$93+Annahmen!$C$94+Annahmen!$C$95)/12+IF(MOD($B14,12)=0,Annahmen!$C$20,0)+IF($B14=Annahmen!$C$8,Annahmen!$C$91,0))) -> -195.24667
B15: 9 | C15: =1/(1+Annahmen!$C$10)^$B15 -> 0.97807483 | D15: =(1+Annahmen!$C$11)^INT(MAX($B15-1,0)/12) -> 1 | E15: =IF($B15>Annahmen!$C$8,0,IF($B15=0,-(Annahmen!$C$33+Annahmen!$C$41)+Annahmen!$C$77,-Annahmen!$C$6/12/100*Annahmen!$C$36*Annahmen!$C$27*$D15-(Annahmen!$C$39+Annahmen!$C$40+Annahmen!$C$42)/12+IF($B15=Annahmen!$C$19,Annahmen!$C$17,0)+IF(MOD($B15,12)=0,Annahmen!$C$20,0)+IF($B15=Annahmen!$C$8,Annahmen!$C$38,0))) -> -149.863 | F15: =IF($B15>Annahmen!$C$8,0,IF($B15=0,-(Annahmen!$C$49+Annahmen!$C$41)+Annahmen!$C$77,-Annahmen!$C$46*(1+Annahmen!$C$48)^INT(($B15-1)/Annahmen!$C$47)-Annahmen!$C$6/12/100*Annahmen!$C$36*Annahmen!$C$27*$D15-(Annahmen!$C$53+Annahmen!$C$54)/12+IF($B15=Annahmen!$C$19,Annahmen!$C$17,0)+IF(MOD($B15,12)=0,Annahmen!$C$20,0)-IF(MOD($B15,Annahmen!$C$47)=0,Annahmen!$C$52,0)-IF(AND(MOD($B15,Annahmen!$C$47)=0,$B15<Annahmen!$C$8),Annahmen!$C$49*(1+Annahmen!$C$48)^($B15/Annahmen!$C$47),0))) -> -388.863 | G15: =IF($B15>Annahmen!$C$8,0,IF($B15=0,-Annahmen!$C$57+Annahmen!$C$77,-Annahmen!$C$6/12/100*Annahmen!$C$58*Annahmen!$C$28*$D15-(Annahmen!$C$61+Annahmen!$C$62+Annahmen!$C$63)/12+IF($B15=Annahmen!$C$8,Annahmen!$C$60,0))) -> -238.5 | H15: =IF($B15>Annahmen!$C$8,0,IF($B15=0,-Annahmen!$C$66,IF($B15<=Annahmen!$C$67*12,-Annahmen!$C$6/12/100*Annahmen!$C$72*$D15-(Annahmen!$C$73+Annahmen!$C$74+Annahmen!$C$75)/12+IF($B15=Annahmen!$C$67*12,Annahmen!$C$76-(Annahmen!$C$81+Annahmen!$C$41),0),-Annahmen!$C$6/12/100*Annahmen!$C$36*Annahmen!$C$27*$D15-(Annahmen!$C$39+Annahmen!$C$40+Annahmen!$C$42)/12+IF(MOD($B15,12)=0,Annahmen!$C$20,0)+IF($B15=Annahmen!$C$8,Annahmen!$C$82,0))+IF($B15=Annahmen!$C$67*12+Annahmen!$C$19,Annahmen!$C$17*Annahmen!$C$21,0))) -> -230.10667 | I15: =IF($B15>Annahmen!$C$8,0,IF($B15=0,-(Annahmen!$C$86+Annahmen!$C$41)+Annahmen!$C$77,-Annahmen!$C$6/12/100*Annahmen!$C$89*Annahmen!$C$27*$D15-(Annahmen!$C$92+Annahmen!$C$93+Annahmen!$C$94+Annahmen!$C$95)/12+IF(MOD($B15,12)=0,Annahmen!$C$20,0)+IF($B15=Annahmen!$C$8,Annahmen!$C$91,0))) -> -195.24667
B16: 10 | C16: =1/(1+Annahmen!$C$10)^$B16 -> 0.97566857 | D16: =(1+Annahmen!$C$11)^INT(MAX($B16-1,0)/12) -> 1 | E16: =IF($B16>Annahmen!$C$8,0,IF($B16=0,-(Annahmen!$C$33+Annahmen!$C$41)+Annahmen!$C$77,-Annahmen!$C$6/12/100*Annahmen!$C$36*Annahmen!$C$27*$D16-(Annahmen!$C$39+Annahmen!$C$40+Annahmen!$C$42)/12+IF($B16=Annahmen!$C$19,Annahmen!$C$17,0)+IF(MOD($B16,12)=0,Annahmen!$C$20,0)+IF($B16=Annahmen!$C$8,Annahmen!$C$38,0))) -> -149.863 | F16: =IF($B16>Annahmen!$C$8,0,IF($B16=0,-(Annahmen!$C$49+Annahmen!$C$41)+Annahmen!$C$77,-Annahmen!$C$46*(1+Annahmen!$C$48)^INT(($B16-1)/Annahmen!$C$47)-Annahmen!$C$6/12/100*Annahmen!$C$36*Annahmen!$C$27*$D16-(Annahmen!$C$53+Annahmen!$C$54)/12+IF($B16=Annahmen!$C$19,Annahmen!$C$17,0)+IF(MOD($B16,12)=0,Annahmen!$C$20,0)-IF(MOD($B16,Annahmen!$C$47)=0,Annahmen!$C$52,0)-IF(AND(MOD($B16,Annahmen!$C$47)=0,$B16<Annahmen!$C$8),Annahmen!$C$49*(1+Annahmen!$C$48)^($B16/Annahmen!$C$47),0))) -> -388.863 | G16: =IF($B16>Annahmen!$C$8,0,IF($B16=0,-Annahmen!$C$57+Annahmen!$C$77,-Annahmen!$C$6/12/100*Annahmen!$C$58*Annahmen!$C$28*$D16-(Annahmen!$C$61+Annahmen!$C$62+Annahmen!$C$63)/12+IF($B16=Annahmen!$C$8,Annahmen!$C$60,0))) -> -238.5 | H16: =IF($B16>Annahmen!$C$8,0,IF($B16=0,-Annahmen!$C$66,IF($B16<=Annahmen!$C$67*12,-Annahmen!$C$6/12/100*Annahmen!$C$72*$D16-(Annahmen!$C$73+Annahmen!$C$74+Annahmen!$C$75)/12+IF($B16=Annahmen!$C$67*12,Annahmen!$C$76-(Annahmen!$C$81+Annahmen!$C$41),0),-Annahmen!$C$6/12/100*Annahmen!$C$36*Annahmen!$C$27*$D16-(Annahmen!$C$39+Annahmen!$C$40+Annahmen!$C$42)/12+IF(MOD($B16,12)=0,Annahmen!$C$20,0)+IF($B16=Annahmen!$C$8,Annahmen!$C$82,0))+IF($B16=Annahmen!$C$67*12+Annahmen!$C$19,Annahmen!$C$17*Annahmen!$C$21,0))) -> -230.10667 | I16: =IF($B16>Annahmen!$C$8,0,IF($B16=0,-(Annahmen!$C$86+Annahmen!$C$41)+Annahmen!$C$77,-Annahmen!$C$6/12/100*Annahmen!$C$89*Annahmen!$C$27*$D16-(Annahmen!$C$92+Annahmen!$C$93+Annahmen!$C$94+Annahmen!$C$95)/12+IF(MOD($B16,12)=0,Annahmen!$C$20,0)+IF($B16=Annahmen!$C$8,Annahmen!$C$91,0))) -> -195.24667
B17: 11 | C17: =1/(1+Annahmen!$C$10)^$B17 -> 0.97326822 | D17: =(1+Annahmen!$C$11)^INT(MAX($B17-1,0)/12) -> 1 | E17: =IF($B17>Annahmen!$C$8,0,IF($B17=0,-(Annahmen!$C$33+Annahmen!$C$41)+Annahmen!$C$77,-Annahmen!$C$6/12/100*Annahmen!$C$36*Annahmen!$C$27*$D17-(Annahmen!$C$39+Annahmen!$C$40+Annahmen!$C$42)/12+IF($B17=Annahmen!$C$19,Annahmen!$C$17,0)+IF(MOD($B17,12)=0,Annahmen!$C$20,0)+IF($B17=Annahmen!$C$8,Annahmen!$C$38,0))) -> -149.863 | F17: =IF($B17>Annahmen!$C$8,0,IF($B17=0,-(Annahmen!$C$49+Annahmen!$C$41)+Annahmen!$C$77,-Annahmen!$C$46*(1+Annahmen!$C$48)^INT(($B17-1)/Annahmen!$C$47)-Annahmen!$C$6/12/100*Annahmen!$C$36*Annahmen!$C$27*$D17-(Annahmen!$C$53+Annahmen!$C$54)/12+IF($B17=Annahmen!$C$19,Annahmen!$C$17,0)+IF(MOD($B17,12)=0,Annahmen!$C$20,0)-IF(MOD($B17,Annahmen!$C$47)=0,Annahmen!$C$52,0)-IF(AND(MOD($B17,Annahmen!$C$47)=0,$B17<Annahmen!$C$8),Annahmen!$C$49*(1+Annahmen!$C$48)^($B17/Annahmen!$C$47),0))) -> -388.863 | G17: =IF($B17>Annahmen!$C$8,0,IF($B17=0,-Annahmen!$C$57+Annahmen!$C$77,-Annahmen!$C$6/12/100*Annahmen!$C$58*Annahmen!$C$28*$D17-(Annahmen!$C$61+Annahmen!$C$62+Annahmen!$C$63)/12+IF($B17=Annahmen!$C$8,Annahmen!$C$60,0))) -> -238.5 | H17: =IF($B17>Annahmen!$C$8,0,IF($B17=0,-Annahmen!$C$66,IF($B17<=Annahmen!$C$67*12,-Annahmen!$C$6/12/100*Annahmen!$C$72*$D17-(Annahmen!$C$73+Annahmen!$C$74+Annahmen!$C$75)/12+IF($B17=Annahmen!$C$67*12,Annahmen!$C$76-(Annahmen!$C$81+Annahmen!$C$41),0),-Annahmen!$C$6/12/100*Annahmen!$C$36*Annahmen!$C$27*$D17-(Annahmen!$C$39+Annahmen!$C$40+Annahmen!$C$42)/12+IF(MOD($B17,12)=0,Annahmen!$C$20,0)+IF($B17=Annahmen!$C$8,Annahmen!$C$82,0))+IF($B17=Annahmen!$C$67*12+Annahmen!$C$19,Annahmen!$C$17*Annahmen!$C$21,0))) -> -230.10667 | I17: =IF($B17>Annahmen!$C$8,0,IF($B17=0,-(Annahmen!$C$86+Annahmen!$C$41)+Annahmen!$C$77,-Annahmen!$C$6/12/100*Annahmen!$C$89*Annahmen!$C$27*$D17-(Annahmen!$C$92+Annahmen!$C$93+Annahmen!$C$94+Annahmen!$C$95)/12+IF(MOD($B17,12)=0,Annahmen!$C$20,0)+IF($B17=Annahmen!$C$8,Annahmen!$C$91,0))) -> -195.24667
... B126: 120 | C126: =1/(1+Annahmen!$C$10)^$B126 -> 0.74409391 | D126: =(1+Annahmen!$C$11)^INT(MAX($B126-1,0)/12) -> 1.1950926 | E126: =IF($B126>Annahmen!$C$8,0,IF($B126=0,-(Annahmen!$C$33+Annahmen!$C$41)+Annahmen!$C$77,-Annahmen!$C$6/12/100*Annahmen!$C$36*Annahmen!$C$27*$D126-(Annahmen!$C$39+Annahmen!$C$40+Annahmen!$C$42)/12+IF($B126=Annahmen!$C$19,Annahmen!$C$17,0)+IF(MOD($B126,12)=0,Annahmen!$C$20,0)+IF($B126=Annahmen!$C$8,Annahmen!$C$38,0))) -> 0 | F126: =IF($B126>Annahmen!$C$8,0,IF($B126=0,-(Annahmen!$C$49+Annahmen!$C$41)+Annahmen!$C$77,-Annahmen!$C$46*(1+Annahmen!$C$48)^INT(($B126-1)/Annahmen!$C$47)-Annahmen!$C$6/12/100*Annahmen!$C$36*Annahmen!$C$27*$D126-(Annahmen!$C$53+Annahmen!$C$54)/12+IF($B126=Annahmen!$C$19,Annahmen!$C$17,0)+IF(MOD($B126,12)=0,Annahmen!$C$20,0)-IF(MOD($B126,Annahmen!$C$47)=0,Annahmen!$C$52,0)-IF(AND(MOD($B126,Annahmen!$C$47)=0,$B126<Annahmen!$C$8),Annahmen!$C$49*(1+Annahmen!$C$48)^($B126/Annahmen!$C$47),0))) -> 0 | G126: =IF($B126>Annahmen!$C$8,0,IF($B126=0,-Annahmen!$C$57+Annahmen!$C$77,-Annahmen!$C$6/12/100*Annahmen!$C$58*Annahmen!$C$28*$D126-(Annahmen!$C$61+Annahmen!$C$62+Annahmen!$C$63)/12+IF($B126=Annahmen!$C$8,Annahmen!$C$60,0))) -> 0 | H126: =IF($B126>Annahmen!$C$8,0,IF($B126=0,-Annahmen!$C$66,IF($B126<=Annahmen!$C$67*12,-Annahmen!$C$6/12/100*Annahmen!$C$72*$D126-(Annahmen!$C$73+Annahmen!$C$74+Annahmen!$C$75)/12+IF($B126=Annahmen!$C$67*12,Annahmen!$C$76-(Annahmen!$C$81+Annahmen!$C$41),0),-Annahmen!$C$6/12/100*Annahmen!$C$36*Annahmen!$C$27*$D126-(Annahmen!$C$39+Annahmen!$C$40+Annahmen!$C$42)/12+IF(MOD($B126,12)=0,Annahmen!$C$20,0)+IF($B126=Annahmen!$C$8,Annahmen!$C$82,0))+IF($B126=Annahmen!$C$67*12+Annahmen!$C$19,Annahmen!$C$17*Annahmen!$C$21,0))) -> 0 | I126: =IF($B126>Annahmen!$C$8,0,IF($B126=0,-(Annahmen!$C$86+Annahmen!$C$41)+Annahmen!$C$77,-Annahmen!$C$6/12/100*Annahmen!$C$89*Annahmen!$C$27*$D126-(Annahmen!$C$92+Annahmen!$C$93+Annahmen!$C$94+Annahmen!$C$95)/12+IF(MOD($B126,12)=0,Annahmen!$C$20,0)+IF($B126=Annahmen!$C$8,Annahmen!$C$91,0))) -> 0
B128: Kapitalwert | D128: Barwert | E128: =SUMPRODUCT($C$6:$C$126,E6:E126) -> -20844.026 | F128: =SUMPRODUCT($C$6:$C$126,F6:F126) -> -21880.165 | G128: =SUMPRODUCT($C$6:$C$126,G6:G126) -> -28638.124 | H128: =SUMPRODUCT($C$6:$C$126,H6:H126) -> -22774.39 | I128: =SUMPRODUCT($C$6:$C$126,I6:I126) -> -21964.645
B129: Nominale Summe (undiskontiert, Kontrolle) | E129: =SUM(E6:E126) -> -20106.847 | F129: =SUM(F6:F126) -> -24298.92 | G129: =SUM(G6:G126) -> -28598.102 | H129: =SUM(H6:H126) -> -22723.969 | I129: =SUM(I6:I126) -> -21556.424
B131: Konvention: Anschaffung, Wallbox und Verkaufserlös in t=0, laufende Zahlungen nachschüssig zum Monatsende, Restwerte im letzten Monat des Horizonts.
B132: A4: bis zum Ende der Restnutzungsdauer LPG-/Benzinbetrieb, im Tauschmonat Verkaufserlös des Altwagens abzüglich Anschaffung des Ersatzfahrzeugs, danach E-Auto-Kostenstruktur.
B133: Die Förderung wird in A4 erst nach dem Tausch ausgezahlt und nur, wenn C21 auf 1 steht.

Sheet Sensitivitaet
B2: Sensitivität: E-Auto sofort kaufen gegen Bestand weiterfahren und später ersetzen
B3: Ausgewiesen ist der Barwertvorteil des sofortigen Kaufs. Positiv (grün) = jetzt kaufen, negativ (rot) = Altwagen weiterfahren und erst später ersetzen.
B4: Da nach dem Tausch beide Alternativen identisch sind, hängt die Differenz nur von den Jahren der Restnutzungsdauer ab. Jährliche Zahlungsweise, Abweichung zum Blatt Ergebnis wenige hundert Euro.
B6: RBF über die Restnutzungsdauer, mit Energiepreissteigerung | C6: =(1-((1+Annahmen!$C$11)/(1+Annahmen!$C$9))^Annahmen!$C$67)/(Annahmen!$C$9-Annahmen!$C$11) -> 1.9323216
B7: RBF über die Restnutzungsdauer, konstante Zahlungen | C7: =((1+Annahmen!$C$9)^Annahmen!$C$67-1)/(Annahmen!$C$9*(1+Annahmen!$C$9)^Annahmen!$C$67) -> 1.9134697
B8: Fahrleistungsunabhängiger Anteil des Barwertvorteils | C8: =(Annahmen!$C$66+$C$7*(Annahmen!$C$73+Annahmen!$C$74+Annahmen!$C$75)-Annahmen!$C$76/(1+Annahmen!$C$9)^Annahmen!$C$67+(Annahmen!$C$81+Annahmen!$C$41)/(1+Annahmen!$C$9)^Annahmen!$C$67-Annahmen!$C$17*Annahmen!$C$21/(1+Annahmen!$C$9)^(Annahmen!$C$67+Annahmen!$C$19/12)-$C$7*(Annahmen!$C$39+Annahmen!$C$40+Annahmen!$C$42-Annahmen!$C$20)-Annahmen!$C$82/(1+Annahmen!$C$9)^Annahmen!$C$7)-((Annahmen!$C$33+Annahmen!$C$41)-Annahmen!$C$77-Annahmen!$C$17/(1+Annahmen!$C$10)^Annahmen!$C$19-Annahmen!$C$33*(1-Annahmen!$C$37)^Annahmen!$C$7/(1+Annahmen!$C$9)^Annahmen!$C$7) -> 1126.4811 | E8: Reparatur, Restwerte, Zinsvorteil des Wartens, Förderungstiming, Fixkosten beider Fahrzeuge
B10: Tabelle 1 Barwertvorteil nach Fahrleistung und Autogaspreis
D11: Autogaspreis LPG (€/l)
B12: Fahrleistung (km/Jahr) | C12: 0.85 | D12: 0.99 | E12: 1.1 | F12: 1.15 | G12: 1.22 | H12: 1.35
B13: 5000 | C13: =$C$8+$C$6*($B13/100)*((Annahmen!$C$71*Annahmen!$C$70*C$12+(1-Annahmen!$C$71)*Annahmen!$C$68*Annahmen!$C$28)-Annahmen!$C$36*Annahmen!$C$27) -> 1341.3263 | D13: =$C$8+$C$6*($B13/100)*((Annahmen!$C$71*Annahmen!$C$70*D$12+(1-Annahmen!$C$71)*Annahmen!$C$68*Annahmen!$C$28)-Annahmen!$C$36*Annahmen!$C$27) -> 1450.8889 | E13: =$C$8+$C$6*($B13/100)*((Annahmen!$C$71*Annahmen!$C$70*E$12+(1-Annahmen!$C$71)*Annahmen!$C$68*Annahmen!$C$28)-Annahmen!$C$36*Annahmen!$C$27) -> 1536.9739 | F13: =$C$8+$C$6*($B13/100)*((Annahmen!$C$71*Annahmen!$C$70*F$12+(1-Annahmen!$C$71)*Annahmen!$C$68*Annahmen!$C$28)-Annahmen!$C$36*Annahmen!$C$27) -> 1576.1034 | G13: =$C$8+$C$6*($B13/100)*((Annahmen!$C$71*Annahmen!$C$70*G$12+(1-Annahmen!$C$71)*Annahmen!$C$68*Annahmen!$C$28)-Annahmen!$C$36*Annahmen!$C$27) -> 1630.8847 | H13: =$C$8+$C$6*($B13/100)*((Annahmen!$C$71*Annahmen!$C$70*H$12+(1-Annahmen!$C$71)*Annahmen!$C$68*Annahmen!$C$28)-Annahmen!$C$36*Annahmen!$C$27) -> 1732.6214
B14: 7500 | C14: =$C$8+$C$6*($B14/100)*((Annahmen!$C$71*Annahmen!$C$70*C$12+(1-Annahmen!$C$71)*Annahmen!$C$68*Annahmen!$C$28)-Annahmen!$C$36*Annahmen!$C$27) -> 1448.7489 | D14: =$C$8+$C$6*($B14/100)*((Annahmen!$C$71*Annahmen!$C$70*D$12+(1-Annahmen!$C$71)*Annahmen!$C$68*Annahmen!$C$28)-Annahmen!$C$36*Annahmen!$C$27) -> 1613.0928 | E14: =$C$8+$C$6*($B14/100)*((Annahmen!$C$71*Annahmen!$C$70*E$12+(1-Annahmen!$C$71)*Annahmen!$C$68*Annahmen!$C$28)-Annahmen!$C$36*Annahmen!$C$27) -> 1742.2202 | F14: =$C$8+$C$6*($B14/100)*((Annahmen!$C$71*Annahmen!$C$70*F$12+(1-Annahmen!$C$71)*Annahmen!$C$68*Annahmen!$C$28)-Annahmen!$C$36*Annahmen!$C$27) -> 1800.9145 | G14: =$C$8+$C$6*($B14/100)*((Annahmen!$C$71*Annahmen!$C$70*G$12+(1-Annahmen!$C$71)*Annahmen!$C$68*Annahmen!$C$28)-Annahmen!$C$36*Annahmen!$C$27) -> 1883.0865 | H14: =$C$8+$C$6*($B14/100)*((Annahmen!$C$71*Annahmen!$C$70*H$12+(1-Annahmen!$C$71)*Annahmen!$C$68*Annahmen!$C$28)-Annahmen!$C$36*Annahmen!$C$27) -> 2035.6916
B15: 10000 | C15: =$C$8+$C$6*($B15/100)*((Annahmen!$C$71*Annahmen!$C$70*C$12+(1-Annahmen!$C$71)*Annahmen!$C$68*Annahmen!$C$28)-Annahmen!$C$36*Annahmen!$C$27) -> 1556.1715 | D15: =$C$8+$C$6*($B15/100)*((Annahmen!$C$71*Annahmen!$C$70*D$12+(1-Annahmen!$C$71)*Annahmen!$C$68*Annahmen!$C$28)-Annahmen!$C$36*Annahmen!$C$27) -> 1775.2968 | E15: =$C$8+$C$6*($B15/100)*((Annahmen!$C$71*Annahmen!$C$70*E$12+(1-Annahmen!$C$71)*Annahmen!$C$68*Annahmen!$C$28)-Annahmen!$C$36*Annahmen!$C$27) -> 1947.4666 | F15: =$C$8+$C$6*($B15/100)*((Annahmen!$C$71*Annahmen!$C$70*F$12+(1-Annahmen!$C$71)*Annahmen!$C$68*Annahmen!$C$28)-Annahmen!$C$36*Annahmen!$C$27) -> 2025.7256 | G15: =$C$8+$C$6*($B15/100)*((Annahmen!$C$71*Annahmen!$C$70*G$12+(1-Annahmen!$C$71)*Annahmen!$C$68*Annahmen!$C$28)-Annahmen!$C$36*Annahmen!$C$27) -> 2135.2883 | H15: =$C$8+$C$6*($B15/100)*((Annahmen!$C$71*Annahmen!$C$70*H$12+(1-Annahmen!$C$71)*Annahmen!$C$68*Annahmen!$C$28)-Annahmen!$C$36*Annahmen!$C$27) -> 2338.7617
B16: 12500 | C16: =$C$8+$C$6*($B16/100)*((Annahmen!$C$71*Annahmen!$C$70*C$12+(1-Annahmen!$C$71)*Annahmen!$C$68*Annahmen!$C$28)-Annahmen!$C$36*Annahmen!$C$27) -> 1663.5941 | D16: =$C$8+$C$6*($B16/100)*((Annahmen!$C$71*Annahmen!$C$70*D$12+(1-Annahmen!$C$71)*Annahmen!$C$68*Annahmen!$C$28)-Annahmen!$C$36*Annahmen!$C$27) -> 1937.5007 | E16: =$C$8+$C$6*($B16/100)*((Annahmen!$C$71*Annahmen!$C$70*E$12+(1-Annahmen!$C$71)*Annahmen!$C$68*Annahmen!$C$28)-Annahmen!$C$36*Annahmen!$C$27) -> 2152.713 | F16: =$C$8+$C$6*($B16/100)*((Annahmen!$C$71*Annahmen!$C$70*F$12+(1-Annahmen!$C$71)*Annahmen!$C$68*Annahmen!$C$28)-Annahmen!$C$36*Annahmen!$C$27) -> 2250.5368 | G16: =$C$8+$C$6*($B16/100)*((Annahmen!$C$71*Annahmen!$C$70*G$12+(1-Annahmen!$C$71)*Annahmen!$C$68*Annahmen!$C$28)-Annahmen!$C$36*Annahmen!$C$27) -> 2387.4901 | H16: =$C$8+$C$6*($B16/100)*((Annahmen!$C$71*Annahmen!$C$70*H$12+(1-Annahmen!$C$71)*Annahmen!$C$68*Annahmen!$C$28)-Annahmen!$C$36*Annahmen!$C$27) -> 2641.8319
B17: 15000 | C17: =$C$8+$C$6*($B17/100)*((Annahmen!$C$71*Annahmen!$C$70*C$12+(1-Annahmen!$C$71)*Annahmen!$C$68*Annahmen!$C$28)-Annahmen!$C$36*Annahmen!$C$27) -> 1771.0167 | D17: =$C$8+$C$6*($B17/100)*((Annahmen!$C$71*Annahmen!$C$70*D$12+(1-Annahmen!$C$71)*Annahmen!$C$68*Annahmen!$C$28)-Annahmen!$C$36*Annahmen!$C$27) -> 2099.7046 | E17: =$C$8+$C$6*($B17/100)*((Annahmen!$C$71*Annahmen!$C$70*E$12+(1-Annahmen!$C$71)*Annahmen!$C$68*Annahmen!$C$28)-Annahmen!$C$36*Annahmen!$C$27) -> 2357.9593 | F17: =$C$8+$C$6*($B17/100)*((Annahmen!$C$71*Annahmen!$C$70*F$12+(1-Annahmen!$C$71)*Annahmen!$C$68*Annahmen!$C$28)-Annahmen!$C$36*Annahmen!$C$27) -> 2475.3479 | G17: =$C$8+$C$6*($B17/100)*((Annahmen!$C$71*Annahmen!$C$70*G$12+(1-Annahmen!$C$71)*Annahmen!$C$68*Annahmen!$C$28)-Annahmen!$C$36*Annahmen!$C$27) -> 2639.6918 | H17: =$C$8+$C$6*($B17/100)*((Annahmen!$C$71*Annahmen!$C$70*H$12+(1-Annahmen!$C$71)*Annahmen!$C$68*Annahmen!$C$28)-Annahmen!$C$36*Annahmen!$C$27) -> 2944.902
B18: 20000 | C18: =$C$8+$C$6*($B18/100)*((Annahmen!$C$71*Annahmen!$C$70*C$12+(1-Annahmen!$C$71)*Annahmen!$C$68*Annahmen!$C$28)-Annahmen!$C$36*Annahmen!$C$27) -> 1985.8618 | D18: =$C$8+$C$6*($B18/100)*((Annahmen!$C$71*Annahmen!$C$70*D$12+(1-Annahmen!$C$71)*Annahmen!$C$68*Annahmen!$C$28)-Annahmen!$C$36*Annahmen!$C$27) -> 2424.1124 | E18: =$C$8+$C$6*($B18/100)*((Annahmen!$C$71*Annahmen!$C$70*E$12+(1-Annahmen!$C$71)*Annahmen!$C$68*Annahmen!$C$28)-Annahmen!$C$36*Annahmen!$C$27) -> 2768.4521 | F18: =$C$8+$C$6*($B18/100)*((Annahmen!$C$71*Annahmen!$C$70*F$12+(1-Annahmen!$C$71)*Annahmen!$C$68*Annahmen!$C$28)-Annahmen!$C$36*Annahmen!$C$27) -> 2924.9701 | G18: =$C$8+$C$6*($B18/100)*((Annahmen!$C$71*Annahmen!$C$70*G$12+(1-Annahmen!$C$71)*Annahmen!$C$68*Annahmen!$C$28)-Annahmen!$C$36*Annahmen!$C$27) -> 3144.0954 | H18: =$C$8+$C$6*($B18/100)*((Annahmen!$C$71*Annahmen!$C$70*H$12+(1-Annahmen!$C$71)*Annahmen!$C$68*Annahmen!$C$28)-Annahmen!$C$36*Annahmen!$C$27) -> 3551.0423
